Workbook

Sheet Registo Inscrições
A1: N.º | B1: N.º Recibo | C1: Data | D1: Nome do Aluno | E1: Ano / Classe | F1: Encarregado de Educação | G1: Contacto / Telefone | H1: N.º Identificação | I1: Taxa Inscrição Qtd | J1: Taxa Inscrição Valor | K1: Seguro Qtd | L1: Seguro Valor | M1: Outros Desc | N1: Outros Qtd | O1: Outros Valor | P1: Desconto | Q1: Forma Pagamento | R1: Referência / Transação | S1: Observações | T1: Status
A2: 1 | B2: EF/001 | C2: 46229 | D2: Hazail Epandi Calei da Costa | E2: Maternelle | F2: Badissadila Mack António da Costa | G2: 941112100 | H2: 022677763OE055 | I2: 1 | J2: 150000 | K2: 1 | L2: 30000 | P2: 18000 | Q2: TPA | R2: 7BB7B2377F6C29BB | T2: Emitido
A3: 2 | B3: EF/002 | C3: 46235 | D3: Erick Libânio Sebastião da Silva | E3: Maternelle P1 | I3: 1 | J3: 150000 | K3: 1 | L3: 30000 | P3: 0 | T3: Emitido
A4: 3 | B4: EF/003 | C4: 46235 | D4: Eloa Marina Sebastião da Silva | E4: Maternelle P2 | I4: 1 | J4: 150000 | K4: 1 | L4: 30000 | P4: 0 | T4: Emitido
A5: 4 | B5: EF/004 | C5: 46240 | D5: Ivander Trindade Bernardo Clementino | E5: Maternelle P2 | I5: 1 | J5: 150000 | K5: 1 | L5: 30000 | P5: 0 | T5: Emitido
A6: 5 | B6: EF/005 | C6: 46237 | D6: Gael Hanji Ventura Quimbundo | E6: Maternelle P3 | I6: 1 | J6: 150000 | K6: 1 | L6: 30000 | P6: 0 | T6: Emitido
A7: 6 | B7: EF/006 | C7: 46240 | D7: Ivanna Chayane Bernardo Clementino | E7: Maternelle P3 | I7: 1 | J7: 150000 | K7: 1 | L7: 30000 | P7: 0 | T7: Emitido
A8: 7 | B8: EF/007 | C8: 46232 | D8: Wendy Aryanne Chimuco Sabino | E8: Maternelle P3 | I8: 1 | J8: 150000 | K8: 1 | L8: 30000 | M8: 1ª Mensalidade | N8: 1 | O8: 170000 | P8: 0 | S8: Inclui 1ª mensalidade | T8: Emitido
A9: 8 | B9: EF/008 | D9: Kesane Aimé Teixeira Correia de Azevedo | E9: Maternelle P1 | P9: 0 | S9: Pagamento FALTA | T9: Pendente
A10: 9 | B10: EF/009 | C10: 46245 | D10: Kuami Hazael Francisco Venâncio | E10: Maternelle P3 | I10: 1 | J10: 150000 | P10: 0 | T10: Emitido
A11: 10 | B11: EF/010 | C11: 46230 | D11: Kaila Abigail Katata da Silva | E11: CM2 | I11: 1 | J11: 150000 | K11: 1 | L11: 30000 | M11: Manuais | N11: 1 | O11: 40000 | P11: 0 | T11: Emitido
A12: 11 | B12: EF/011 | C12: 46229 | D12: Pedro Henriques Simão dos Santos | E12: CM2 | I12: 1 | J12: 150000 | K12: 1 | L12: 30000 | M12: Manuais | N12: 1 | O12: 54000 | P12: 0 | T12: Emitido
A13: 12 | B13: EF/012 | C13: 46239 | D13: Keane António Teixeira Correia de Azevedo | E13: CM2 | I13: 1 | J13: 150000 | P13: 0 | S13: Pagamento do Seguro em FALTA | T13: Emitido
A14: 13 | B14: EF/013 | C14: 46245 | D14: Márcio Uzziel Francisco Venâncio | E14: CM2 | I14: 1 | J14: 150000 | P14: 0 | T14: Emitido
A15: 14 | B15: EF/014 | C15: 46229 | D15: Nathaniel Dialude Calei da Costa | E15: 4eme | F15: Badissadila Mack António da Costa | G15: 941112100 | I15: 1 | J15: 150000 | K15: 1 | L15: 30000 | P15: 18000 | S15: Desconto 10% 2º irmão | T15: Emitido
A17: INSTRUÇÕES: Dados sincronizados a partir do Controlo de Propinas (Contabilidade). Preencha Encarregado, Telefone, BI, Forma de Pagamento e Referência (amarelo). No recibo digite o N.º (coluna A) em H1 (recibo 1) ou H29 (recibo 2).

Sheet Recibo de Inscrição
H1: 7
B2: ÉCOLE CONSULAIRE DU CONGO (Brazzaville) DE LUANDA | H2: ← N.º Recibo 1 (não imprime)
B3: Escola de Ensino Francês – Estabelecimento Consular, Filial Nova Vida
B4: Luanda, Angola | Escola consular – Isenta de impostos
B5: RECIBO DE PAGAMENTO DE INSCRIÇÃO
B6: N.º do Recibo: | C6: =IFERROR(INDEX('Registo Inscrições'!B:B,MATCH($H$1,'Registo Inscrições'!$A:$A,0)),"") -> EF/007 | D6: Data: | E6: =IFERROR(IF(INDEX('Registo Inscrições'!C:C,MATCH($H$1,'Registo Inscrições'!$A:$A,0))="",TODAY(),INDEX('Registo Inscrições'!C:C,MATCH($H$1,'Registo Inscrições'!$A:$A,0))),TODAY()) -> 46232
B7: DADOS DO ALUNO E ENCARREGADO DE EDUCAÇÃO
B8: Nome do Aluno: | C8: =IFERROR(INDEX('Registo Inscrições'!D:D,MATCH($H$1,'Registo Inscrições'!$A:$A,0)),"") -> Wendy Aryanne Chimuco Sabino
B9: Ano / Classe: | C9: =IFERROR(INDEX('Registo Inscrições'!E:E,MATCH($H$1,'Registo Inscrições'!$A:$A,0)),"") -> Maternelle P3
B10: Encarregado de Educação: | C10: =IFERROR(INDEX('Registo Inscrições'!F:F,MATCH($H$1,'Registo Inscrições'!$A:$A,0)),"") -> 0
B11: Contacto / Telefone: | C11: =IFERROR(INDEX('Registo Inscrições'!G:G,MATCH($H$1,'Registo Inscrições'!$A:$A,0)),"") -> 0
B12: N.º de Identificação (BI/Passaporte): | C12: =IFERROR(INDEX('Registo Inscrições'!H:H,MATCH($H$1,'Registo Inscrições'!$A:$A,0)),"") -> 0
B13: DETALHES DO PAGAMENTO
B14: Descrição | C14: Qtd | D14: Valor Unitário | E14: Total
B15: Taxa de Inscrição – Ano Letivo 2026 / 2027 | C15: =IFERROR(INDEX('Registo Inscrições'!I:I,MATCH($H$1,'Registo Inscrições'!$A:$A,0)),"") -> 1 | D15: =IFERROR(INDEX('Registo Inscrições'!J:J,MATCH($H$1,'Registo Inscrições'!$A:$A,0)),"") -> 150000 | E15: =IF(OR(C15="",D15=""),0,C15*D15) -> 150000
B16: Seguro Escolar | C16: =IFERROR(INDEX('Registo Inscrições'!K:K,MATCH($H$1,'Registo Inscrições'!$A:$A,0)),"") -> 1 | D16: =IFERROR(INDEX('Registo Inscrições'!L:L,MATCH($H$1,'Registo Inscrições'!$A:$A,0)),"") -> 30000 | E16: =IF(OR(C16="",D16=""),0,C16*D16) -> 30000
B17: Outros: | C17: =IFERROR(INDEX('Registo Inscrições'!N:N,MATCH($H$1,'Registo Inscrições'!$A:$A,0)),"") -> 1 | D17: =IFERROR(INDEX('Registo Inscrições'!O:O,MATCH($H$1,'Registo Inscrições'!$A:$A,0)),"") -> 170000 | E17: =IF(OR(C17="",D17=""),0,C17*D17) -> 170000
B18: Desconto 10% (2º irmão) | E18: =IFERROR(-ABS(INDEX('Registo Inscrições'!P:P,MATCH($H$1,'Registo Inscrições'!$A:$A,0))),0) -> 0
B19: TOTAL A PAGAR | E19: =SUM(E15:E18) -> 350000
B20: Forma de Pagamento: | C20: =IFERROR("☐ Numerário ☐ Transferência Bancária ☐ Outro: "&INDEX('Registo Inscrições'!Q:Q,MATCH($H$1,'Registo Inscrições'!$A:$A,0)),"☐ Numerário ☐ Transferência Bancária ☐ Outro: ") -> ☐ Numerário ☐ Transferência Bancária ☐ Outro:
B21: Referência / N.º de Transação: | C21: =IFERROR(INDEX('Registo Inscrições'!R:R,MATCH($H$1,'Registo Inscrições'!$A:$A,0)),"") -> 0
B22: NOTA: Este estabelecimento é uma escola consular do Congo. Nos termos da legislação aplicável e do estatuto consular, não está sujeita ao pagamento de impostos (incluindo IVA). O presente recibo não inclui qualquer valor de imposto.
B23: Recebido por (Escola): | D23: Encarregado de Educação:
B24: Nome: _________________________ | D24: Nome: _________________________
B25: Assinatura / Carimbo: | D25: Assinatura:
B26: Data: ____/____/________ | D26: Data: ____/____/________
B27: Documento gerado para efeitos de comprovativo de pagamento • Conservar este recibo
B28: École Consulaire du Congo Brazzaville de Luanda – Escola Consular • Isenta de impostos
B30: ✂ - - - - - - - - - - - - - - - CORTAR AQUI - - - - - - - - - - - - - - - ✂ | H30: 10
B32: ÉCOLE CONSULAIRE DU CONGO (Brazzaville) DE LUANDA | H32: ← N.º Recibo 2 (não imprime)
B33: Escola de Ensino Francês – Estabelecimento Consular, Filial Nova Vida
B34: Luanda, Angola | Escola consular – Isenta de impostos
B35: RECIBO DE PAGAMENTO DE INSCRIÇÃO
B36: N.º do Recibo: | C36: =IFERROR(INDEX('Registo Inscrições'!B:B,MATCH($H$30,'Registo Inscrições'!$A:$A,0)),"") -> EF/010 | D36: Data: | E36: =IFERROR(IF(INDEX('Registo Inscrições'!C:C,MATCH($H$30,'Registo Inscrições'!$A:$A,0))="",TODAY(),INDEX('Registo Inscrições'!C:C,MATCH($H$30,'Registo Inscrições'!$A:$A,0))),TODAY()) -> 46230
B37: DADOS DO ALUNO E ENCARREGADO DE EDUCAÇÃO
B38: Nome do Aluno: | C38: =IFERROR(INDEX('Registo Inscrições'!D:D,MATCH($H$30,'Registo Inscrições'!$A:$A,0)),"") -> Kaila Abigail Katata da Silva
B39: Ano / Classe: | C39: =IFERROR(INDEX('Registo Inscrições'!E:E,MATCH($H$30,'Registo Inscrições'!$A:$A,0)),"") -> CM2
B40: Encarregado de Educação: | C40: =IFERROR(INDEX('Registo Inscrições'!F:F,MATCH($H$30,'Registo Inscrições'!$A:$A,0)),"") -> 0
B41: Contacto / Telefone: | C41: =IFERROR(INDEX('Registo Inscrições'!G:G,MATCH($H$30,'Registo Inscrições'!$A:$A,0)),"") -> 0
B42: N.º de Identificação (BI/Passaporte): | C42: =IFERROR(INDEX('Registo Inscrições'!H:H,MATCH($H$30,'Registo Inscrições'!$A:$A,0)),"") -> 0
...

Sheet Recibos Fundo Maneio
A1: ÉCOLE CONSULAIRE DU CONGO (Brazzaville) DE LUANDA – REGISTO DE RECIBOS FUNDO DE MANEIO
A2: N.º Recibo e Status automáticos • Amarelo = preencher • Verde = calculado • Digite RM-xxx no modelo de impressão para gerar o recibo
A3: N.º Recibo | B3: Data | C3: Descrição | D3: Valor (KZ) | E3: Quem recebeu | F3: Qualidade | G3: Origem / Fundo | H3: Observações | I3: Status
A4: RM-001 | B4: 46240 | C4: Pagamento mão-de-obra pintor | D4: 44000 | E4: Pedro | F4: Prestador de serviço / Colaborador | G4: Fundo de Maneio | I4: =IF(C4="","",IF(B4="","Pendente","Emitido")) -> Emitido
A5: RM-002 | B5: 46240 | C5: Pagamento transporte pintor | D5: 2000 | E5: Pedro | F5: Prestador de serviço / Colaborador | G5: Fundo de Maneio | I5: =IF(C5="","",IF(B5="","Pendente","Emitido")) -> Emitido
A6: RM-003 | B6: 46242 | C6: Compra Braçadeiras e fio para esteiras | D6: 10000 | E6: Paulino Nfinda | F6: Prestador de serviço / Colaborador | G6: Fundo de Maneio | I6: =IF(C6="","",IF(B6="","Pendente","Emitido")) -> Emitido
A7: RM-004 | B7: 46242 | C7: Transporte p/ entrega de panfletos GAMEK | D7: 1000 | E7: Francisco Kativa | F7: Prestador de serviço / Colaborador | G7: Fundo de Maneio | I7: =IF(C7="","",IF(B7="","Pendente","Emitido")) -> Emitido
A8: RM-005 | B8: 46242 | C8: Compra Saco Cimento Cola e transporte | D8: 4000 | E8: Pedro | F8: Prestador de serviço / Colaborador | G8: Fundo de Maneio | I8: =IF(C8="","",IF(B8="","Pendente","Emitido")) -> Emitido
A9: RM-006 | B9: 46242 | C9: Empréstimo Dona Cristina | D9: 2000 | E9: Dna. Cristina | F9: Prestador de serviço / Colaborador | G9: Fundo de Maneio | I9: =IF(C9="","",IF(B9="","Pendente","Emitido")) -> Emitido
A10: RM-007 | B10: 46242 | C10: Transporte p/ serralheiro | D10: 3000 | E10: Paulino Nfinda | F10: Prestador de serviço / Colaborador | G10: Fundo de Maneio | I10: =IF(C10="","",IF(B10="","Pendente","Emitido")) -> Emitido
A11: RM-008 | B11: 46243 | C11: Transporte funcionário p/ compra do gesso e etc | D11: 2400 | E11: Pedro | F11: Prestador de serviço / Colaborador | G11: Fundo de Maneio | I11: =IF(C11="","",IF(B11="","Pendente","Emitido")) -> Emitido
A12: RM-009 | B12: 46245 | C12: Transporte p/ deslocação técnico do gerador | D12: 2000 | E12: Flávio | F12: Prestador de serviço / Colaborador | G12: Fundo de Maneio | I12: =IF(C12="","",IF(B12="","Pendente","Emitido")) -> Emitido
A13: RM-010 | B13: 46245 | C13: Adiantamento p/ pintor | D13: 6000 | E13: Pedro | F13: Prestador de serviço / Colaborador | G13: Fundo de Maneio | I13: =IF(C13="","",IF(B13="","Pendente","Emitido")) -> Emitido
A14: RM-011 | B14: 46251 | C14: Fatura 142 - CASA COMERCIAL | D14: 18000 | E14: Pedro | F14: Prestador de serviço / Colaborador | G14: Fundo de Maneio | H14: Fatura 142 | I14: =IF(C14="","",IF(B14="","Pendente","Emitido")) -> Emitido
A15: RM-012 | B15: 46251 | C15: Botija de gás | D15: 2000 | E15: Francisco Kativa | F15: Prestador de serviço / Colaborador | G15: Fundo de Maneio | I15: =IF(C15="","",IF(B15="","Pendente","Emitido")) -> Emitido
A16: RM-013 | B16: 46251 | C16: Compra de Saco Arroz | D16: 8750 | E16: Francisco Kativa | F16: Prestador de serviço / Colaborador | G16: Fundo de Maneio | H16: FR2026/21650 | I16: =IF(C16="","",IF(B16="","Pendente","Emitido")) -> Emitido
A17: RM-014 | B17: 46251 | C17: Transporte p/ funcionário compras | D17: 1250 | E17: Francisco Kativa | F17: Prestador de serviço / Colaborador | G17: Fundo de Maneio | I17: =IF(C17="","",IF(B17="","Pendente","Emitido")) -> Emitido
A18: RM-015 | B18: 46251 | C18: Compra pão e Sheltox p/ seguranças | D18: 7000 | E18: Alberto | F18: Prestador de serviço / Colaborador | G18: Fundo de Maneio | I18: =IF(C18="","",IF(B18="","Pendente","Emitido")) -> Emitido
A19: RM-016 | B19: 46251 | C19: Adiantamento p/ pintor | D19: 6000 | E19: Pedro | F19: Prestador de serviço / Colaborador | G19: Fundo de Maneio | I19: =IF(C19="","",IF(B19="","Pendente","Emitido")) -> Emitido
A20: RM-017 | I20: =IF(C20="","",IF(B20="","Pendente","Emitido"))
A21: RM-018 | I21: =IF(C21="","",IF(B21="","Pendente","Emitido"))
A22: RM-019 | I22: =IF(C22="","",IF(B22="","Pendente","Emitido"))
A23: =IF(C23="","","RM-"&TEXT(COUNTA($C$4:C23),"000")) | I23: =IF(C23="","",IF(B23="","Pendente","Emitido"))
A24: =IF(C24="","","RM-"&TEXT(COUNTA($C$4:C24),"000")) | I24: =IF(C24="","",IF(B24="","Pendente","Emitido"))
A25: =IF(C25="","","RM-"&TEXT(COUNTA($C$4:C25),"000")) | I25: =IF(C25="","",IF(B25="","Pendente","Emitido"))
A26: =IF(C26="","","RM-"&TEXT(COUNTA($C$4:C26),"000")) | I26: =IF(C26="","",IF(B26="","Pendente","Emitido"))
A27: =IF(C27="","","RM-"&TEXT(COUNTA($C$4:C27),"000")) | I27: =IF(C27="","",IF(B27="","Pendente","Emitido"))
A28: =IF(C28="","","RM-"&TEXT(COUNTA($C$4:C28),"000")) | I28: =IF(C28="","",IF(B28="","Pendente","Emitido"))
A29: =IF(C29="","","RM-"&TEXT(COUNTA($C$4:C29),"000")) | I29: =IF(C29="","",IF(B29="","Pendente","Emitido"))
A30: =IF(C30="","","RM-"&TEXT(COUNTA($C$4:C30),"000")) | I30: =IF(C30="","",IF(B30="","Pendente","Emitido"))
A31: =IF(C31="","","RM-"&TEXT(COUNTA($C$4:C31),"000")) | I31: =IF(C31="","",IF(B31="","Pendente","Emitido"))
A32: =IF(C32="","","RM-"&TEXT(COUNTA($C$4:C32),"000")) | I32: =IF(C32="","",IF(B32="","Pendente","Emitido"))
A33: =IF(C33="","","RM-"&TEXT(COUNTA($C$4:C33),"000")) | I33: =IF(C33="","",IF(B33="","Pendente","Emitido"))
A34: =IF(C34="","","RM-"&TEXT(COUNTA($C$4:C34),"000")) | I34: =IF(C34="","",IF(B34="","Pendente","Emitido"))
... A53: =IF(C53="","","RM-"&TEXT(COUNTA($C$4:C53),"000")) | I53: =IF(C53="","",IF(B53="","Pendente","Emitido"))
A54: TOTAL | D54: =SUM(D4:D53) -> 119400

Sheet Modelo Recibo Maneio
A1: ÉCOLE CONSULAIRE DU CONGO (Brazzaville) DE LUANDA
A2: Escola Consular – Filial Nova Vida | Isenta de impostos
A3: RECIBO DE PAGAMENTO EM DINHEIRO (FUNDO DE MANEIO)
A4: N.º Recibo: | B4: RM-015 | D4: Data emissão: | E4: =TODAY() -> 46255
A5: BENEFICIÁRIO
A6: Nome: | B6: =IF(B4="","",IFERROR(INDEX('Recibos Fundo Maneio'!E:E,MATCH(B4,'Recibos Fundo Maneio'!A:A,0)),"")) -> Alberto | D6: Qualidade: | E6: =IF(B4="","",IFERROR(INDEX('Recibos Fundo Maneio'!F:F,MATCH(B4,'Recibos Fundo Maneio'!A:A,0)),"")) -> Prestador de serviço / Colaborador
A7: Data pag.: | B7: =IF(B4="","",IFERROR(INDEX('Recibos Fundo Maneio'!B:B,MATCH(B4,'Recibos Fundo Maneio'!A:A,0)),"")) -> 46251
A8: DETALHES DO PAGAMENTO
A9: Descrição | D9: Valor (KZ) | E9: Origem
A10: =IF(B4="","",IFERROR(INDEX('Recibos Fundo Maneio'!C:C,MATCH(B4,'Recibos Fundo Maneio'!A:A,0)),"")) -> Compra pão e Sheltox p/ seguranças | D10: =IF(B4="","",IFERROR(INDEX('Recibos Fundo Maneio'!D:D,MATCH(B4,'Recibos Fundo Maneio'!A:A,0)),"")) -> 7000 | E10: =IF(B4="","",IFERROR(INDEX('Recibos Fundo Maneio'!G:G,MATCH(B4,'Recibos Fundo Maneio'!A:A,0)),"")) -> Fundo de Maneio
A11: TOTAL PAGO: | D11: =D10 -> 7000
A12: DECLARAÇÃO
A13: =IF(B4="","","Declaro ter recebido a quantia de "&TEXT(D10,"#,##0.00")&" KZ (em dinheiro) referente a: "&A10&". Pagamento efetuado a partir do Fundo de Maneio da Escola.") -> Declaro ter recebido a quantia de 7000,0.00 KZ (em dinheiro) referente a: Compra pão e Sheltox p/ seguranças. Pagamento efetuado a partir do Fundo de Maneio da Escola.
A15: O Recebedor | D15: Pela Escola (Caixa / Direção)
A16: Nome: ____________________ | D16: Nome: ____________________
A17: Assinatura: _______________ | D17: Assinatura / Carimbo: ______
A18: Data: ____/____/________ | D18: Data: ____/____/________
A19: Documento comprovativo • Conservar este recibo • Escola Consular – Isenta de impostos
A20: ✂ - - - - - - - - - - - - - CORTAR AQUI - - - - - - - - - - - - - ✂
A21: ÉCOLE CONSULAIRE DU CONGO (Brazzaville) DE LUANDA
A22: Escola Consular – Filial Nova Vida | Isenta de impostos
A23: RECIBO DE PAGAMENTO EM DINHEIRO (FUNDO DE MANEIO)
A24: N.º Recibo: | B24: RM-016 | D24: Data emissão: | E24: =TODAY() -> 46255
A25: BENEFICIÁRIO
A26: Nome: | B26: =IF(B24="","",IFERROR(INDEX('Recibos Fundo Maneio'!E:E,MATCH(B24,'Recibos Fundo Maneio'!A:A,0)),"")) -> Pedro | D26: Qualidade: | E26: =IF(B24="","",IFERROR(INDEX('Recibos Fundo Maneio'!F:F,MATCH(B24,'Recibos Fundo Maneio'!A:A,0)),"")) -> Prestador de serviço / Colaborador
A27: Data pag.: | B27: =IF(B24="","",IFERROR(INDEX('Recibos Fundo Maneio'!B:B,MATCH(B24,'Recibos Fundo Maneio'!A:A,0)),"")) -> 46251
A28: DETALHES DO PAGAMENTO
A29: Descrição | D29: Valor (KZ) | E29: Origem
A30: =IF(B24="","",IFERROR(INDEX('Recibos Fundo Maneio'!C:C,MATCH(B24,'Recibos Fundo Maneio'!A:A,0)),"")) -> Adiantamento p/ pintor | D30: =IF(B24="","",IFERROR(INDEX('Recibos Fundo Maneio'!D:D,MATCH(B24,'Recibos Fundo Maneio'!A:A,0)),"")) -> 6000 | E30: =IF(B24="","",IFERROR(INDEX('Recibos Fundo Maneio'!G:G,MATCH(B24,'Recibos Fundo Maneio'!A:A,0)),"")) -> Fundo de Maneio
A31: TOTAL PAGO: | D31: =D30 -> 6000
A32: DECLARAÇÃO
A33: =IF(B24="","","Declaro ter recebido a quantia de "&TEXT(D30,"#,##0.00")&" KZ (em dinheiro) referente a: "&A30&". Pagamento efetuado a partir do Fundo de Maneio da Escola.") -> Declaro ter recebido a quantia de 6000,0.00 KZ (em dinheiro) referente a: Adiantamento p/ pintor. Pagamento efetuado a partir do Fundo de Maneio da Escola.
A35: O Recebedor | D35: Pela Escola (Caixa / Direção)
A36: Nome: ____________________ | D36: Nome: ____________________
A37: Assinatura: _______________ | D37: Assinatura / Carimbo: ______
A38: Data: ____/____/________ | D38: Data: ____/____/________
A39: Documento comprovativo • Conservar este recibo • Escola Consular – Isenta de impostos
A40: ✂ - - - - - - - - - - - - - CORTAR AQUI - - - - - - - - - - - - - ✂
A41: ÉCOLE CONSULAIRE DU CONGO (Brazzaville) DE LUANDA
A42: Escola Consular – Filial Nova Vida | Isenta de impostos
...

Sheet RM-001
B2: ÉCOLE CONSULAIRE DU CONGO (Brazzaville) DE LUANDA
B3: Escola de Ensino Francês – Estabelecimento Consular, Filial Nova Vida
B4: Luanda, Angola | Escola consular – Isenta de impostos
B6: RECIBO DE PAGAMENTO EM DINHEIRO (FUNDO DE MANEIO)
B8: N.º do Recibo: | C8: RM-001 | D8: Data: | E8: 46240
B10: DADOS DO BENEFICIÁRIO / RECEBEDOR
B11: Nome / Quem recebeu: | C11: Pedro
B12: Qualidade: | C12: Prestador de serviço / Fornecedor / Colaborador
B14: DETALHES DO PAGAMENTO
B15: Descrição | C15: Valor (KZ) | D15: Forma | E15: Origem
B16: Pagamento mão-de-obra pintor | C16: 44000 | D16: Dinheiro (Fundo de Maneio) | E16: Fundo de Maneio – Levantamento 06-08
B18: TOTAL PAGO | C18: 44000
B20: DECLARAÇÃO
B21: Declaro ter recebido a quantia de 44,000.00 KZ (em dinheiro) referente a: Pagamento mão-de-obra pintor. O pagamento foi efetuado a partir do Fundo de Maneio da Escola.
B24: O Recebedor | D24: Pela Escola (Caixa / Direção)
B26: Nome: _________________________ | D26: Nome: _________________________
B27: Assinatura: ____________________ | D27: Assinatura / Carimbo: __________
B28: Data: ____/____/________ | D28: Data: ____/____/________
B30: Documento gerado para efeitos de comprovativo de pagamento em dinheiro • Conservar este recibo
B31: École Consulaire du Congo Brazzaville de Luanda – Escola Consular • Isenta de impostos

Sheet RM-002
B2: ÉCOLE CONSULAIRE DU CONGO (Brazzaville) DE LUANDA
B3: Escola de Ensino Francês – Estabelecimento Consular, Filial Nova Vida
B4: Luanda, Angola | Escola consular – Isenta de impostos
B6: RECIBO DE PAGAMENTO EM DINHEIRO (FUNDO DE MANEIO)
B8: N.º do Recibo: | C8: RM-002 | D8: Data: | E8: 46240
B10: DADOS DO BENEFICIÁRIO / RECEBEDOR
B11: Nome / Quem recebeu: | C11: Pedro
B12: Qualidade: | C12: Prestador de serviço / Fornecedor / Colaborador
B14: DETALHES DO PAGAMENTO
B15: Descrição | C15: Valor (KZ) | D15: Forma | E15: Origem
B16: Pagamento transporte pintor | C16: 2000 | D16: Dinheiro (Fundo de Maneio) | E16: Fundo de Maneio – Levantamento 06-08
B18: TOTAL PAGO | C18: 2000
B20: DECLARAÇÃO
B21: Declaro ter recebido a quantia de 2,000.00 KZ (em dinheiro) referente a: Pagamento transporte pintor. O pagamento foi efetuado a partir do Fundo de Maneio da Escola.
B24: O Recebedor | D24: Pela Escola (Caixa / Direção)
B26: Nome: _________________________ | D26: Nome: _________________________
B27: Assinatura: ____________________ | D27: Assinatura / Carimbo: __________
B28: Data: ____/____/________ | D28: Data: ____/____/________
B30: Documento gerado para efeitos de comprovativo de pagamento em dinheiro • Conservar este recibo
B31: École Consulaire du Congo Brazzaville de Luanda – Escola Consular • Isenta de impostos

Sheet RM-003
B2: ÉCOLE CONSULAIRE DU CONGO (Brazzaville) DE LUANDA
B3: Escola de Ensino Francês – Estabelecimento Consular, Filial Nova Vida
B4: Luanda, Angola | Escola consular – Isenta de impostos
B6: RECIBO DE PAGAMENTO EM DINHEIRO (FUNDO DE MANEIO)
B8: N.º do Recibo: | C8: RM-003 | D8: Data: | E8: 46242
B10: DADOS DO BENEFICIÁRIO / RECEBEDOR
B11: Nome / Quem recebeu: | C11: Paulino Nfinda
B12: Qualidade: | C12: Prestador de serviço / Fornecedor / Colaborador
B14: DETALHES DO PAGAMENTO
B15: Descrição | C15: Valor (KZ) | D15: Forma | E15: Origem
B16: Compra Braçadeiras e fio para esteiras | C16: 10000 | D16: Dinheiro (Fundo de Maneio) | E16: Fundo de Maneio – Levantamento 08-08
B18: TOTAL PAGO | C18: 10000
B20: DECLARAÇÃO
B21: Declaro ter recebido a quantia de 10,000.00 KZ (em dinheiro) referente a: Compra Braçadeiras e fio para esteiras. O pagamento foi efetuado a partir do Fundo de Maneio da Escola.
B24: O Recebedor | D24: Pela Escola (Caixa / Direção)
B26: Nome: _________________________ | D26: Nome: _________________________
B27: Assinatura: ____________________ | D27: Assinatura / Carimbo: __________
B28: Data: ____/____/________ | D28: Data: ____/____/________
B30: Documento gerado para efeitos de comprovativo de pagamento em dinheiro • Conservar este recibo
B31: École Consulaire du Congo Brazzaville de Luanda – Escola Consular • Isenta de impostos

Sheet RM-004
B2: ÉCOLE CONSULAIRE DU CONGO (Brazzaville) DE LUANDA
B3: Escola de Ensino Francês – Estabelecimento Consular, Filial Nova Vida
B4: Luanda, Angola | Escola consular – Isenta de impostos
B6: RECIBO DE PAGAMENTO EM DINHEIRO (FUNDO DE MANEIO)
B8: N.º do Recibo: | C8: RM-004 | D8: Data: | E8: 46242
B10: DADOS DO BENEFICIÁRIO / RECEBEDOR
B11: Nome / Quem recebeu: | C11: Francisco Kativa
B12: Qualidade: | C12: Prestador de serviço / Fornecedor / Colaborador
B14: DETALHES DO PAGAMENTO
B15: Descrição | C15: Valor (KZ) | D15: Forma | E15: Origem
B16: Transporte p/ entrega de panfletos GAMEK | C16: 1000 | D16: Dinheiro (Fundo de Maneio) | E16: Fundo de Maneio – Levantamento 08-08
B18: TOTAL PAGO | C18: 1000
B20: DECLARAÇÃO
B21: Declaro ter recebido a quantia de 1,000.00 KZ (em dinheiro) referente a: Transporte p/ entrega de panfletos GAMEK. O pagamento foi efetuado a partir do Fundo de Maneio da Escola.
B24: O Recebedor | D24: Pela Escola (Caixa / Direção)
B26: Nome: _________________________ | D26: Nome: _________________________
B27: Assinatura: ____________________ | D27: Assinatura / Carimbo: __________
B28: Data: ____/____/________ | D28: Data: ____/____/________
B30: Documento gerado para efeitos de comprovativo de pagamento em dinheiro • Conservar este recibo
B31: École Consulaire du Congo Brazzaville de Luanda – Escola Consular • Isenta de impostos

Sheet RM-005
B2: ÉCOLE CONSULAIRE DU CONGO (Brazzaville) DE LUANDA
B3: Escola de Ensino Francês – Estabelecimento Consular, Filial Nova Vida
B4: Luanda, Angola | Escola consular – Isenta de impostos
B6: RECIBO DE PAGAMENTO EM DINHEIRO (FUNDO DE MANEIO)
B8: N.º do Recibo: | C8: RM-005 | D8: Data: | E8: 46242
B10: DADOS DO BENEFICIÁRIO / RECEBEDOR
B11: Nome / Quem recebeu: | C11: Pedro
B12: Qualidade: | C12: Prestador de serviço / Fornecedor / Colaborador
B14: DETALHES DO PAGAMENTO
B15: Descrição | C15: Valor (KZ) | D15: Forma | E15: Origem
B16: Compra Saco Cimento Cola e transporte | C16: 4000 | D16: Dinheiro (Fundo de Maneio) | E16: Fundo de Maneio – Levantamento 08-08
B18: TOTAL PAGO | C18: 4000
B20: DECLARAÇÃO
B21: Declaro ter recebido a quantia de 4,000.00 KZ (em dinheiro) referente a: Compra Saco Cimento Cola e transporte. O pagamento foi efetuado a partir do Fundo de Maneio da Escola.
B24: O Recebedor | D24: Pela Escola (Caixa / Direção)
B26: Nome: _________________________ | D26: Nome: _________________________
B27: Assinatura: ____________________ | D27: Assinatura / Carimbo: __________
B28: Data: ____/____/________ | D28: Data: ____/____/________
B30: Documento gerado para efeitos de comprovativo de pagamento em dinheiro • Conservar este recibo
B31: École Consulaire du Congo Brazzaville de Luanda – Escola Consular • Isenta de impostos

Sheet RM-006
B2: ÉCOLE CONSULAIRE DU CONGO (Brazzaville) DE LUANDA
B3: Escola de Ensino Francês – Estabelecimento Consular, Filial Nova Vida
B4: Luanda, Angola | Escola consular – Isenta de impostos
B6: RECIBO DE PAGAMENTO EM DINHEIRO (FUNDO DE MANEIO)
B8: N.º do Recibo: | C8: RM-006 | D8: Data: | E8: 46242
B10: DADOS DO BENEFICIÁRIO / RECEBEDOR
B11: Nome / Quem recebeu: | C11: Dna. Cristina
B12: Qualidade: | C12: Prestador de serviço / Fornecedor / Colaborador
B14: DETALHES DO PAGAMENTO
B15: Descrição | C15: Valor (KZ) | D15: Forma | E15: Origem
B16: Empréstimo Dona Cristina | C16: 2000 | D16: Dinheiro (Fundo de Maneio) | E16: Fundo de Maneio – Levantamento 08-08
B18: TOTAL PAGO | C18: 2000
B20: DECLARAÇÃO
B21: Declaro ter recebido a quantia de 2,000.00 KZ (em dinheiro) referente a: Empréstimo Dona Cristina. O pagamento foi efetuado a partir do Fundo de Maneio da Escola.
B24: O Recebedor | D24: Pela Escola (Caixa / Direção)
B26: Nome: _________________________ | D26: Nome: _________________________
B27: Assinatura: ____________________ | D27: Assinatura / Carimbo: __________
B28: Data: ____/____/________ | D28: Data: ____/____/________
B30: Documento gerado para efeitos de comprovativo de pagamento em dinheiro • Conservar este recibo
B31: École Consulaire du Congo Brazzaville de Luanda – Escola Consular • Isenta de impostos

Sheet RM-007
B2: ÉCOLE CONSULAIRE DU CONGO (Brazzaville) DE LUANDA
B3: Escola de Ensino Francês – Estabelecimento Consular, Filial Nova Vida
B4: Luanda, Angola | Escola consular – Isenta de impostos
B6: RECIBO DE PAGAMENTO EM DINHEIRO (FUNDO DE MANEIO)
B8: N.º do Recibo: | C8: RM-007 | D8: Data: | E8: 46242
B10: DADOS DO BENEFICIÁRIO / RECEBEDOR
B11: Nome / Quem recebeu: | C11: Paulino Nfinda
B12: Qualidade: | C12: Prestador de serviço / Fornecedor / Colaborador
B14: DETALHES DO PAGAMENTO
B15: Descrição | C15: Valor (KZ) | D15: Forma | E15: Origem
B16: Transporte p/ serralheiro | C16: 3000 | D16: Dinheiro (Fundo de Maneio) | E16: Fundo de Maneio – Levantamento 08-08
B18: TOTAL PAGO | C18: 3000
B20: DECLARAÇÃO
B21: Declaro ter recebido a quantia de 3,000.00 KZ (em dinheiro) referente a: Transporte p/ serralheiro. O pagamento foi efetuado a partir do Fundo de Maneio da Escola.
B24: O Recebedor | D24: Pela Escola (Caixa / Direção)
B26: Nome: _________________________ | D26: Nome: _________________________
B27: Assinatura: ____________________ | D27: Assinatura / Carimbo: __________
B28: Data: ____/____/________ | D28: Data: ____/____/________
B30: Documento gerado para efeitos de comprovativo de pagamento em dinheiro • Conservar este recibo
B31: École Consulaire du Congo Brazzaville de Luanda – Escola Consular • Isenta de impostos

Sheet RM-008
B2: ÉCOLE CONSULAIRE DU CONGO (Brazzaville) DE LUANDA
B3: Escola de Ensino Francês – Estabelecimento Consular, Filial Nova Vida
B4: Luanda, Angola | Escola consular – Isenta de impostos
B6: RECIBO DE PAGAMENTO EM DINHEIRO (FUNDO DE MANEIO)
B8: N.º do Recibo: | C8: RM-008 | D8: Data: | E8: 46243
B10: DADOS DO BENEFICIÁRIO / RECEBEDOR
B11: Nome / Quem recebeu: | C11: Pedro
B12: Qualidade: | C12: Prestador de serviço / Fornecedor / Colaborador
B14: DETALHES DO PAGAMENTO
B15: Descrição | C15: Valor (KZ) | D15: Forma | E15: Origem
B16: Transporte funcionário p/ compra do gesso e etc | C16: 2400 | D16: Dinheiro (Fundo de Maneio) | E16: Fundo de Maneio – Levantamento 09-08
B18: TOTAL PAGO | C18: 2400
B20: DECLARAÇÃO
B21: Declaro ter recebido a quantia de 2,400.00 KZ (em dinheiro) referente a: Transporte funcionário p/ compra do gesso e etc. O pagamento foi efetuado a partir do Fundo de Maneio da Escola.
B24: O Recebedor | D24: Pela Escola (Caixa / Direção)
B26: Nome: _________________________ | D26: Nome: _________________________
B27: Assinatura: ____________________ | D27: Assinatura / Carimbo: __________
B28: Data: ____/____/________ | D28: Data: ____/____/________
B30: Documento gerado para efeitos de comprovativo de pagamento em dinheiro • Conservar este recibo
B31: École Consulaire du Congo Brazzaville de Luanda – Escola Consular • Isenta de impostos

Sheet RM-009
B2: ÉCOLE CONSULAIRE DU CONGO (Brazzaville) DE LUANDA
B3: Escola de Ensino Francês – Estabelecimento Consular, Filial Nova Vida
B4: Luanda, Angola | Escola consular – Isenta de impostos
B6: RECIBO DE PAGAMENTO EM DINHEIRO (FUNDO DE MANEIO)
B8: N.º do Recibo: | C8: RM-009 | D8: Data: | E8: 46245
B10: DADOS DO BENEFICIÁRIO / RECEBEDOR
B11: Nome / Quem recebeu: | C11: Flávio
B12: Qualidade: | C12: Prestador de serviço / Fornecedor / Colaborador
B14: DETALHES DO PAGAMENTO
B15: Descrição | C15: Valor (KZ) | D15: Forma | E15: Origem
B16: Transporte p/ deslocação técnico do gerador | C16: 2000 | D16: Dinheiro (Fundo de Maneio) | E16: Fundo de Maneio – Levantamento 11-08
B18: TOTAL PAGO | C18: 2000
B20: DECLARAÇÃO
B21: Declaro ter recebido a quantia de 2,000.00 KZ (em dinheiro) referente a: Transporte p/ deslocação técnico do gerador. O pagamento foi efetuado a partir do Fundo de Maneio da Escola.
B24: O Recebedor | D24: Pela Escola (Caixa / Direção)
B26: Nome: _________________________ | D26: Nome: _________________________
B27: Assinatura: ____________________ | D27: Assinatura / Carimbo: __________
B28: Data: ____/____/________ | D28: Data: ____/____/________
B30: Documento gerado para efeitos de comprovativo de pagamento em dinheiro • Conservar este recibo
B31: École Consulaire du Congo Brazzaville de Luanda – Escola Consular • Isenta de impostos

Sheet RM-010
B2: ÉCOLE CONSULAIRE DU CONGO (Brazzaville) DE LUANDA
B3: Escola de Ensino Francês – Estabelecimento Consular, Filial Nova Vida
B4: Luanda, Angola | Escola consular – Isenta de impostos
B6: RECIBO DE PAGAMENTO EM DINHEIRO (FUNDO DE MANEIO)
B8: N.º do Recibo: | C8: RM-010 | D8: Data: | E8: 46245
B10: DADOS DO BENEFICIÁRIO / RECEBEDOR
B11: Nome / Quem recebeu: | C11: Pedro
B12: Qualidade: | C12: Prestador de serviço / Fornecedor / Colaborador
B14: DETALHES DO PAGAMENTO
B15: Descrição | C15: Valor (KZ) | D15: Forma | E15: Origem
B16: Adiantamento p/ pintor | C16: 6000 | D16: Dinheiro (Fundo de Maneio) | E16: Fundo de Maneio – Levantamento 11-08
B18: TOTAL PAGO | C18: 6000
B20: DECLARAÇÃO
B21: Declaro ter recebido a quantia de 6,000.00 KZ (em dinheiro) referente a: Adiantamento p/ pintor. O pagamento foi efetuado a partir do Fundo de Maneio da Escola.
B24: O Recebedor | D24: Pela Escola (Caixa / Direção)
B26: Nome: _________________________ | D26: Nome: _________________________
B27: Assinatura: ____________________ | D27: Assinatura / Carimbo: __________
B28: Data: ____/____/________ | D28: Data: ____/____/________
B30: Documento gerado para efeitos de comprovativo de pagamento em dinheiro • Conservar este recibo
B31: École Consulaire du Congo Brazzaville de Luanda – Escola Consular • Isenta de impostos
