Workbook

Sheet Dashboard
B2: DASHBOARD FINANCEIRO ESCOLAR | École Consulaire du Congo - Luanda | 2026/2027
B3: Valores atualizados automaticamente a partir do Controlo de Propinas, Mensalidades, Fluxo de Caixa e DRE
B5: TOTAL INSCRICOES (c/ desc.) | D5: =SUMIF('Controlo de Propinas'!J6:J256,">0") -> 170000 | G5: RESULTADO LIQUIDO (DRE) | K5: ='Controlo de Propinas'!N295 -> 3258000
B6: ='Controlo de Propinas'!N295 -> 3258000 | D6: =SUMIF('Controlo de Propinas'!J6:J105,">0")+SUMIF('Controlo de Propinas'!J110:J124,">0")+SUMIF('Controlo de Propinas'!J129:J187,">0")+SUMIF('Controlo de Propinas'!J192:J206,">0")+SUMIF('Controlo de Propinas'!J210:J248,">0")+SUMIF('Controlo de Propinas'!J253:J292,">0") -> 170000 | G6: =DRE!B25 -> -1730379.9 | K6: ='Controlo de Propinas'!N295 -> 3258000
B9: ALUNOS INSCRITOS | D9: SALDO DE CAIXA | G9: DESCONTOS CONCEDIDOS | K9: TAXA COBRANCA SET/26
B10: =COUNTA('Controlo de Propinas'!B6:B105)+COUNTA('Controlo de Propinas'!B110:B124)+COUNTA('Controlo de Propinas'!B129:B187)+COUNTA('Controlo de Propinas'!B192:B206)+COUNTA('Controlo de Propinas'!B210:B248)+COUNTA('Controlo de Propinas'!B253:B292) -> 17 | D10: ='Fluxo de Caixa'!H6 -> 3058000 | G10: ='Controlo de Propinas'!L295-'Controlo de Propinas'!N295 -> 36000 | K10: =IF(COUNTA(Mensalidades!A6:A12)=0,0,COUNTIF(Mensalidades!E6:E12,">0")/7) -> 0
B12: RECEITAS POR GRUPO (Inscricoes c/ desconto)
B13: Grupo | C13: Alunos | D13: Valor Bruto | E13: Valor c/ Desc.
B14: Maternelle | C14: =COUNTA('Controlo de Propinas'!B6:B105) -> 9 | D14: ='Controlo de Propinas'!L106 -> 1730000 | E14: ='Controlo de Propinas'!N106 -> 1712000
B15: CM1 | C15: =COUNTA('Controlo de Propinas'!B110:B124) -> 1 | D15: ='Controlo de Propinas'!L125 -> 180000 | E15: ='Controlo de Propinas'!N125 -> 180000
B16: CM2 | C16: =COUNTA('Controlo de Propinas'!B129:B187) -> 4 | D16: ='Controlo de Propinas'!L188 -> 834000 | E16: ='Controlo de Propinas'!N188 -> 834000
B17: 6eme | C17: =COUNTA('Controlo de Propinas'!B192:B206) -> 1 | D17: ='Controlo de Propinas'!L207 -> 180000 | E17: ='Controlo de Propinas'!N207 -> 180000
B18: 4eme | C18: =COUNTA('Controlo de Propinas'!B210:B248) -> 1 | D18: ='Controlo de Propinas'!L249 -> 180000 | E18: ='Controlo de Propinas'!N249 -> 162000
B19: TOTAL | C19: =C14+C15+C16+C17+C18 -> 16 | D19: ='Controlo de Propinas'!L295 -> 3294000 | E19: ='Controlo de Propinas'!N295 -> 3258000
B21: DRE RESUMIDO
B22: Proveitos de Inscricoes | C22: =DRE!B4 -> 3088000
B23: Proveitos de Propinas | C23: =DRE!B5 -> 170000
B24: Outros Proveitos | C24: =DRE!B6+DRE!B7 -> 0
B25: TOTAL PROVEITOS | C25: =DRE!B8 -> 3258000
B26: TOTAL CUSTOS | C26: =DRE!B23 -> 4988379.9
B27: RESULTADO LIQUIDO
B29: FLUXO DE CAIXA (resumo mensal)
B30: Mes | C30: Inscricoes | D30: Propinas | E30: Saldo Acum.
B31: Jul/26 | C31: ='Fluxo de Caixa'!B4 -> 1168000 | D31: ='Fluxo de Caixa'!C4 -> 170000 | E31: ='Fluxo de Caixa'!H4 -> 2826379.9
B32: Ago/26 | C32: ='Fluxo de Caixa'!B5 -> 1720000 | D32: ='Fluxo de Caixa'!C5 -> 0 | E32: ='Fluxo de Caixa'!H5 -> 3058000
B33: Set/26 | C33: ='Fluxo de Caixa'!B6 -> 0 | D33: ='Fluxo de Caixa'!C6 -> 0 | E33: ='Fluxo de Caixa'!H6 -> 3058000
B34: Out/26 | C34: ='Fluxo de Caixa'!B7 -> 0 | D34: ='Fluxo de Caixa'!C7 -> 0 | E34: ='Fluxo de Caixa'!H7 -> 3058000
B35: Nov/26 | C35: ='Fluxo de Caixa'!B8 -> 0 | D35: ='Fluxo de Caixa'!C8 -> 0 | E35: ='Fluxo de Caixa'!H8 -> 3058000
B36: Dez/26
B38: STATUS MENSALIDADES (Setembro)
B39: Alunos com pagamento em Set/26 | C39: =COUNTIF(Mensalidades!E6:E80,">0")+COUNTIF(Mensalidades!E85:E159,">0")+COUNTIF(Mensalidades!E164:E238,">0")+COUNTIF(Mensalidades!E243:E317,">0") -> 0
B40: Alunos pendentes (Setembro) | C40: =COUNTIFS(Mensalidades!B6:B80,"<>",Mensalidades!E6:E80,0)+COUNTIFS(Mensalidades!B85:B159,"<>",Mensalidades!E85:E159,0)+COUNTIFS(Mensalidades!B164:B238,"<>",Mensalidades!E164:E238,0)+COUNTIFS(Mensalidades!B243:B317,"<>",Mensalidades!E243:E317,0) -> 212
B41: Valor recebido em Setembro
B43: DESCONTOS POR PARENTESCO
B44: Familias com 2 irmaos (10%) | C44: 3 | D44: Sebastiao da Silva | Calei da Costa | Bernardo Clementino
B45: Filhos unicos (0%) | C45: 4 | D45: Gael, Wendy, Pedro, Kaila
B46: Total descontos concedidos (KZ)
B48: NOTA: Todos os valores sao calculados automaticamente. Atualize Controlo de Propinas ou Mensalidades para refletir alteracoes no Dashboard.
B49: Ecole Consulaire du Congo (Brazzaville) de Luanda • Escola consular – Isenta de impostos • Dashboard financeiro

Sheet Plano de Contas
A1: PLANO GERAL DE CONTABILIDADE (PGC)
A2: CÓDIGO | B2: DESCRIÇÃO
A3: 11 | B3: Imobilizações Corpóreas
A4: 31 | B4: Clientes (Alunos)
A5: 36 | B5: Pessoal
A6: 41 | B6: Bancos
A7: 61 | B7: Compras / Manuais Escolares
A8: 62 | B8: Despesas com Atividades Extracurriculares
A9: 71 | B9: Custo Pessoal
A10: 81 | B10: Proveitos de propinas
A11: 82 | B11: Proveitos Atividades Extra
A12: 83 | B12: Outros Proveitos

Sheet Controlo de Propinas
A1: CONTROLO DE INSCRIÇÕES / MATRÍCULAS – 2026/2027
A2: Amarelo = preencher | Verde = calculado | Desconto: 2 irmãos 10% • 3=15% • 4+=20% | A4 landscape
A4: ▶ MATERNELLE
A5: ID | B5: Nome Aluno | C5: Turma | D5: Inscrição | E5: Manuais | F5: Uniforme | G5: Seguro | H5: Ativ. Extras | I5: Curso Intensivo | J5: 1ª Mensal. | K5: Data Pag. | L5: Valor Bruto | M5: Desc. % | N5: Valor c/ Desc. | O5: Observações
A6: P1-01 | B6: Hazail Epandi Calei da Costa | C6: Maternelle | D6: 150000 | G6: 30000 | K6: 46229 | L6: =IF(B6="","",SUM(D6:J6)) -> 180000 | M6: 0.1 | N6: =IF(B6="","",L6*(1-IF(M6="",0,M6))) -> 162000
A7: P1-02 | B7: Erick Libânio Sebastião da Silva | C7: Maternelle P1 | D7: 150000 | G7: 30000 | K7: 46235 | L7: =IF(B7="","",SUM(D7:J7)) -> 180000 | M7: 0 | N7: =IF(B7="","",L7*(1-IF(M7="",0,M7))) -> 180000
A8: P2-03 | B8: Eloa Marina Sebastião da Silva | C8: Maternelle P2 | D8: 150000 | G8: 30000 | K8: 46235 | L8: =IF(B8="","",SUM(D8:J8)) -> 180000 | M8: 0 | N8: =IF(B8="","",L8*(1-IF(M8="",0,M8))) -> 180000
A9: P2-04 | B9: Ivander Trindade Bernardo Clementino | C9: Maternelle P2 | D9: 150000 | G9: 30000 | K9: 46240 | L9: =IF(B9="","",SUM(D9:J9)) -> 180000 | M9: 0 | N9: =IF(B9="","",L9*(1-IF(M9="",0,M9))) -> 180000
A10: P3-05 | B10: Gael Hanji Ventura Quimbundo | C10: Maternelle P3 | D10: 150000 | G10: 30000 | K10: 46237 | L10: =IF(B10="","",SUM(D10:J10)) -> 180000 | M10: 0 | N10: =IF(B10="","",L10*(1-IF(M10="",0,M10))) -> 180000
A11: P3-06 | B11: Ivanna Chayane Bernardo Clementino | C11: Maternelle P3 | D11: 150000 | G11: 30000 | K11: 46240 | L11: =IF(B11="","",SUM(D11:J11)) -> 180000 | M11: 0 | N11: =IF(B11="","",L11*(1-IF(M11="",0,M11))) -> 180000
A12: P3-07 | B12: Wendy Aryanne Chimuco Sabino | C12: Maternelle P3 | D12: 150000 | G12: 30000 | J12: 170000 | K12: 46232 | L12: =IF(B12="","",SUM(D12:J12)) -> 350000 | M12: 0 | N12: =IF(B12="","",L12*(1-IF(M12="",0,M12))) -> 350000
A13: P1-08 | B13: Kesane Aimé Teixeira Correia de Azevedo | C13: Maternelle P1 | D13: 150000 | G13: 0 | K13: 46255 | L13: =IF(B13="","",SUM(D13:J13)) -> 150000 | M13: 0 | N13: =IF(B13="","",L13*(1-IF(M13="",0,M13))) -> 150000
A14: P3-09 | B14: Kuami Hazael Francisco Venâncio | C14: Maternelle P3 | D14: 150000 | G14: 0 | K14: 46245 | L14: =IF(B14="","",SUM(D14:J14)) -> 150000 | M14: 0 | N14: =IF(B14="","",L14*(1-IF(M14="",0,M14))) -> 150000
L15: =IF(B15="","",SUM(D15:J15)) | N15: =IF(B15="","",L15*(1-IF(M15="",0,M15)))
L16: =IF(B16="","",SUM(D16:J16)) | N16: =IF(B16="","",L16*(1-IF(M16="",0,M16)))
L17: =IF(B17="","",SUM(D17:J17)) | N17: =IF(B17="","",L17*(1-IF(M17="",0,M17)))
L18: =IF(B18="","",SUM(D18:J18)) | N18: =IF(B18="","",L18*(1-IF(M18="",0,M18)))
L19: =IF(B19="","",SUM(D19:J19)) | N19: =IF(B19="","",L19*(1-IF(M19="",0,M19)))
L20: =IF(B20="","",SUM(D20:J20)) | N20: =IF(B20="","",L20*(1-IF(M20="",0,M20)))
L21: =IF(B21="","",SUM(D21:J21)) | N21: =IF(B21="","",L21*(1-IF(M21="",0,M21)))
L22: =IF(B22="","",SUM(D22:J22)) | N22: =IF(B22="","",L22*(1-IF(M22="",0,M22)))
L23: =IF(B23="","",SUM(D23:J23)) | N23: =IF(B23="","",L23*(1-IF(M23="",0,M23)))
L24: =IF(B24="","",SUM(D24:J24)) | N24: =IF(B24="","",L24*(1-IF(M24="",0,M24)))
L25: =IF(B25="","",SUM(D25:J25)) | N25: =IF(B25="","",L25*(1-IF(M25="",0,M25)))
L26: =IF(B26="","",SUM(D26:J26)) | N26: =IF(B26="","",L26*(1-IF(M26="",0,M26)))
... L105: =IF(B105="","",SUM(D105:J105)) | N105: =IF(B105="","",L105*(1-IF(M105="",0,M105)))
A106: Subtotal | B106: =COUNTIF(B6:B105,"?*")&" alunos" -> 9 alunos | L106: =SUM(L6:L105) -> 1730000 | N106: =SUM(N6:N105) -> 1712000
A108: ▶ CM1
A109: ID | B109: Nome Aluno | C109: Turma | D109: Inscrição | E109: Manuais | F109: Uniforme | G109: Seguro | H109: Ativ. Extras | I109: Curso Intensivo | J109: 1ª Mensal. | K109: Data Pag. | L109: Valor Bruto | M109: Desc. % | N109: Valor c/ Desc. | O109: Observações
A110: CM1-01 | B110: Crisber Uluwami António Cristovão De Sousa | C110: CM1 | D110: 150000 | G110: 30000 | K110: 46252 | L110: =IF(B110="","",SUM(D110:J110)) -> 180000 | N110: =IF(B110="","",L110*(1-IF(M110="",0,M110))) -> 180000
A111: CM1-02 | C111: CM1 | L111: =IF(B111="","",SUM(D111:J111)) | N111: =IF(B111="","",L111*(1-IF(M111="",0,M111)))
C112: CM1 | L112: =IF(B112="","",SUM(D112:J112)) | N112: =IF(B112="","",L112*(1-IF(M112="",0,M112)))
C113: CM1 | L113: =IF(B113="","",SUM(D113:J113)) | N113: =IF(B113="","",L113*(1-IF(M113="",0,M113)))
C114: CM1 | L114: =IF(B114="","",SUM(D114:J114)) | N114: =IF(B114="","",L114*(1-IF(M114="",0,M114)))
C115: CM1 | L115: =IF(B115="","",SUM(D115:J115)) | N115: =IF(B115="","",L115*(1-IF(M115="",0,M115)))
C116: CM1 | L116: =IF(B116="","",SUM(D116:J116)) | N116: =IF(B116="","",L116*(1-IF(M116="",0,M116)))
C117: CM1 | L117: =IF(B117="","",SUM(D117:J117)) | N117: =IF(B117="","",L117*(1-IF(M117="",0,M117)))
C118: CM1 | L118: =IF(B118="","",SUM(D118:J118)) | N118: =IF(B118="","",L118*(1-IF(M118="",0,M118)))
C119: CM1 | L119: =IF(B119="","",SUM(D119:J119)) | N119: =IF(B119="","",L119*(1-IF(M119="",0,M119)))
C120: CM1 | L120: =IF(B120="","",SUM(D120:J120)) | N120: =IF(B120="","",L120*(1-IF(M120="",0,M120)))
...

Sheet Mensalidades
A1: CONTROLO DE MENSALIDADES – 2026/2027
A2: Ligado ao Controlo de Propinas | Amarelo = pago no mês | Verde = calculado | Status: Pendente / Parcial / Pago | A4 landscape
A4: ▶ MATERNELLE (até 75 alunos)
A5: ID | B5: Nome Aluno | C5: Turma | D5: Propina | E5: Set | F5: Out | G5: Nov | H5: Dez | I5: Jan | J5: Fev | K5: Mar | L5: Abr | M5: Mai | N5: Jun | O5: Total | P5: Status | Q5: Obs.
A6: =IF('Controlo de Propinas'!A6="","",'Controlo de Propinas'!A6) -> P1-01 | B6: =IF('Controlo de Propinas'!B6="","",'Controlo de Propinas'!B6) -> Hazail Epandi Calei da Costa | C6: =IF('Controlo de Propinas'!C6="","",'Controlo de Propinas'!C6) -> Maternelle | D6: =IF(C6="","",IF(OR(C6="Maternelle",C6="Maternelle P1",C6="Maternelle P2",C6="Maternelle P3"),170000,IF(C6="CM2",250000,IF(C6="4eme",260000,170000)))) -> 170000 | E6: 0 | F6: 0 | G6: 0 | H6: 0 | I6: 0 | J6: 0 | K6: 0 | L6: 0 | M6: 0 | N6: 0 | O6: =IF(B6="","",SUM(E6:N6)) -> 0 | P6: =IF(B6="","",IF(O6=0,"Pendente",IF(O6<D6,"Parcial","Pago"))) -> Pendente
A7: =IF('Controlo de Propinas'!A7="","",'Controlo de Propinas'!A7) -> P1-02 | B7: =IF('Controlo de Propinas'!B7="","",'Controlo de Propinas'!B7) -> Erick Libânio Sebastião da Silva | C7: =IF('Controlo de Propinas'!C7="","",'Controlo de Propinas'!C7) -> Maternelle P1 | D7: =IF(C7="","",IF(OR(C7="Maternelle",C7="Maternelle P1",C7="Maternelle P2",C7="Maternelle P3"),170000,IF(C7="CM2",250000,IF(C7="4eme",260000,170000)))) -> 170000 | E7: 0 | F7: 0 | G7: 0 | H7: 0 | I7: 0 | J7: 0 | K7: 0 | L7: 0 | M7: 0 | N7: 0 | O7: =IF(B7="","",SUM(E7:N7)) -> 0 | P7: =IF(B7="","",IF(O7=0,"Pendente",IF(O7<D7,"Parcial","Pago"))) -> Pendente
A8: =IF('Controlo de Propinas'!A8="","",'Controlo de Propinas'!A8) -> P2-03 | B8: =IF('Controlo de Propinas'!B8="","",'Controlo de Propinas'!B8) -> Eloa Marina Sebastião da Silva | C8: =IF('Controlo de Propinas'!C8="","",'Controlo de Propinas'!C8) -> Maternelle P2 | D8: =IF(C8="","",IF(OR(C8="Maternelle",C8="Maternelle P1",C8="Maternelle P2",C8="Maternelle P3"),170000,IF(C8="CM2",250000,IF(C8="4eme",260000,170000)))) -> 170000 | E8: 0 | F8: 0 | G8: 0 | H8: 0 | I8: 0 | J8: 0 | K8: 0 | L8: 0 | M8: 0 | N8: 0 | O8: =IF(B8="","",SUM(E8:N8)) -> 0 | P8: =IF(B8="","",IF(O8=0,"Pendente",IF(O8<D8,"Parcial","Pago"))) -> Pendente
A9: =IF('Controlo de Propinas'!A9="","",'Controlo de Propinas'!A9) -> P2-04 | B9: =IF('Controlo de Propinas'!B9="","",'Controlo de Propinas'!B9) -> Ivander Trindade Bernardo Clementino | C9: =IF('Controlo de Propinas'!C9="","",'Controlo de Propinas'!C9) -> Maternelle P2 | D9: =IF(C9="","",IF(OR(C9="Maternelle",C9="Maternelle P1",C9="Maternelle P2",C9="Maternelle P3"),170000,IF(C9="CM2",250000,IF(C9="4eme",260000,170000)))) -> 170000 | E9: 0 | F9: 0 | G9: 0 | H9: 0 | I9: 0 | J9: 0 | K9: 0 | L9: 0 | M9: 0 | N9: 0 | O9: =IF(B9="","",SUM(E9:N9)) -> 0 | P9: =IF(B9="","",IF(O9=0,"Pendente",IF(O9<D9,"Parcial","Pago"))) -> Pendente
A10: =IF('Controlo de Propinas'!A10="","",'Controlo de Propinas'!A10) -> P3-05 | B10: =IF('Controlo de Propinas'!B10="","",'Controlo de Propinas'!B10) -> Gael Hanji Ventura Quimbundo | C10: =IF('Controlo de Propinas'!C10="","",'Controlo de Propinas'!C10) -> Maternelle P3 | D10: =IF(C10="","",IF(OR(C10="Maternelle",C10="Maternelle P1",C10="Maternelle P2",C10="Maternelle P3"),170000,IF(C10="CM2",250000,IF(C10="4eme",260000,170000)))) -> 170000 | E10: 0 | F10: 0 | G10: 0 | H10: 0 | I10: 0 | J10: 0 | K10: 0 | L10: 0 | M10: 0 | N10: 0 | O10: =IF(B10="","",SUM(E10:N10)) -> 0 | P10: =IF(B10="","",IF(O10=0,"Pendente",IF(O10<D10,"Parcial","Pago"))) -> Pendente
A11: =IF('Controlo de Propinas'!A11="","",'Controlo de Propinas'!A11) -> P3-06 | B11: =IF('Controlo de Propinas'!B11="","",'Controlo de Propinas'!B11) -> Ivanna Chayane Bernardo Clementino | C11: =IF('Controlo de Propinas'!C11="","",'Controlo de Propinas'!C11) -> Maternelle P3 | D11: =IF(C11="","",IF(OR(C11="Maternelle",C11="Maternelle P1",C11="Maternelle P2",C11="Maternelle P3"),170000,IF(C11="CM2",250000,IF(C11="4eme",260000,170000)))) -> 170000 | E11: 0 | F11: 0 | G11: 0 | H11: 0 | I11: 0 | J11: 0 | K11: 0 | L11: 0 | M11: 0 | N11: 0 | O11: =IF(B11="","",SUM(E11:N11)) -> 0 | P11: =IF(B11="","",IF(O11=0,"Pendente",IF(O11<D11,"Parcial","Pago"))) -> Pendente
A12: =IF('Controlo de Propinas'!A12="","",'Controlo de Propinas'!A12) -> P3-07 | B12: =IF('Controlo de Propinas'!B12="","",'Controlo de Propinas'!B12) -> Wendy Aryanne Chimuco Sabino | C12: =IF('Controlo de Propinas'!C12="","",'Controlo de Propinas'!C12) -> Maternelle P3 | D12: =IF(C12="","",IF(OR(C12="Maternelle",C12="Maternelle P1",C12="Maternelle P2",C12="Maternelle P3"),170000,IF(C12="CM2",250000,IF(C12="4eme",260000,170000)))) -> 170000 | E12: 0 | F12: 0 | G12: 0 | H12: 0 | I12: 0 | J12: 0 | K12: 0 | L12: 0 | M12: 0 | N12: 0 | O12: =IF(B12="","",SUM(E12:N12)) -> 0 | P12: =IF(B12="","",IF(O12=0,"Pendente",IF(O12<D12,"Parcial","Pago"))) -> Pendente
A13: =IF('Controlo de Propinas'!A13="","",'Controlo de Propinas'!A13) -> P1-08 | B13: =IF('Controlo de Propinas'!B13="","",'Controlo de Propinas'!B13) -> Kesane Aimé Teixeira Correia de Azevedo | C13: =IF('Controlo de Propinas'!C13="","",'Controlo de Propinas'!C13) -> Maternelle P1 | D13: =IF(C13="","",IF(OR(C13="Maternelle",C13="Maternelle P1",C13="Maternelle P2",C13="Maternelle P3"),170000,IF(C13="CM2",250000,IF(C13="4eme",260000,170000)))) -> 170000 | E13: 0 | F13: 0 | G13: 0 | H13: 0 | I13: 0 | J13: 0 | K13: 0 | L13: 0 | M13: 0 | N13: 0 | O13: =IF(B13="","",SUM(E13:N13)) -> 0 | P13: =IF(B13="","",IF(O13=0,"Pendente",IF(O13<D13,"Parcial","Pago"))) -> Pendente
A14: =IF('Controlo de Propinas'!A14="","",'Controlo de Propinas'!A14) -> P3-09 | B14: =IF('Controlo de Propinas'!B14="","",'Controlo de Propinas'!B14) -> Kuami Hazael Francisco Venâncio | C14: =IF('Controlo de Propinas'!C14="","",'Controlo de Propinas'!C14) -> Maternelle P3 | D14: =IF(C14="","",IF(OR(C14="Maternelle",C14="Maternelle P1",C14="Maternelle P2",C14="Maternelle P3"),170000,IF(C14="CM2",250000,IF(C14="4eme",260000,170000)))) -> 170000 | E14: 0 | F14: 0 | G14: 0 | H14: 0 | I14: 0 | J14: 0 | K14: 0 | L14: 0 | M14: 0 | N14: 0 | O14: =IF(B14="","",SUM(E14:N14)) -> 0 | P14: =IF(B14="","",IF(O14=0,"Pendente",IF(O14<D14,"Parcial","Pago"))) -> Pendente
A15: =IF('Controlo de Propinas'!A15="","",'Controlo de Propinas'!A15) | B15: =IF('Controlo de Propinas'!B15="","",'Controlo de Propinas'!B15) | C15: =IF('Controlo de Propinas'!C15="","",'Controlo de Propinas'!C15) | D15: =IF(C15="","",IF(OR(C15="Maternelle",C15="Maternelle P1",C15="Maternelle P2",C15="Maternelle P3"),170000,IF(C15="CM2",250000,IF(C15="4eme",260000,170000)))) | E15: 0 | F15: 0 | G15: 0 | H15: 0 | I15: 0 | J15: 0 | K15: 0 | L15: 0 | M15: 0 | N15: 0 | O15: =IF(B15="","",SUM(E15:N15)) | P15: =IF(B15="","",IF(O15=0,"Pendente",IF(O15<D15,"Parcial","Pago")))
A16: =IF('Controlo de Propinas'!A16="","",'Controlo de Propinas'!A16) | B16: =IF('Controlo de Propinas'!B16="","",'Controlo de Propinas'!B16) | C16: =IF('Controlo de Propinas'!C16="","",'Controlo de Propinas'!C16) | D16: =IF(C16="","",IF(OR(C16="Maternelle",C16="Maternelle P1",C16="Maternelle P2",C16="Maternelle P3"),170000,IF(C16="CM2",250000,IF(C16="4eme",260000,170000)))) | E16: 0 | F16: 0 | G16: 0 | H16: 0 | I16: 0 | J16: 0 | K16: 0 | L16: 0 | M16: 0 | N16: 0 | O16: =IF(B16="","",SUM(E16:N16)) | P16: =IF(B16="","",IF(O16=0,"Pendente",IF(O16<D16,"Parcial","Pago")))
A17: =IF('Controlo de Propinas'!A17="","",'Controlo de Propinas'!A17) | B17: =IF('Controlo de Propinas'!B17="","",'Controlo de Propinas'!B17) | C17: =IF('Controlo de Propinas'!C17="","",'Controlo de Propinas'!C17) | D17: =IF(C17="","",IF(OR(C17="Maternelle",C17="Maternelle P1",C17="Maternelle P2",C17="Maternelle P3"),170000,IF(C17="CM2",250000,IF(C17="4eme",260000,170000)))) | E17: 0 | F17: 0 | G17: 0 | H17: 0 | I17: 0 | J17: 0 | K17: 0 | L17: 0 | M17: 0 | N17: 0 | O17: =IF(B17="","",SUM(E17:N17)) | P17: =IF(B17="","",IF(O17=0,"Pendente",IF(O17<D17,"Parcial","Pago")))
... A80: =IF('Controlo de Propinas'!A80="","",'Controlo de Propinas'!A80) | B80: =IF('Controlo de Propinas'!B80="","",'Controlo de Propinas'!B80) | C80: =IF('Controlo de Propinas'!C80="","",'Controlo de Propinas'!C80) | D80: =IF(C80="","",IF(OR(C80="Maternelle",C80="Maternelle P1",C80="Maternelle P2",C80="Maternelle P3"),170000,IF(C80="CM2",250000,IF(C80="4eme",260000,170000)))) | E80: 0 | F80: 0 | G80: 0 | H80: 0 | I80: 0 | J80: 0 | K80: 0 | L80: 0 | M80: 0 | N80: 0 | O80: =IF(B80="","",SUM(E80:N80)) | P80: =IF(B80="","",IF(O80=0,"Pendente",IF(O80<D80,"Parcial","Pago")))
A81: Subtotal | B81: =COUNTIF(B6:B80,"?*")&" alunos" -> 9 alunos | E81: =SUM(E6:E80) -> 0 | F81: =SUM(F6:F80) -> 0 | G81: =SUM(G6:G80) -> 0 | H81: =SUM(H6:H80) -> 0 | I81: =SUM(I6:I80) -> 0 | J81: =SUM(J6:J80) -> 0 | K81: =SUM(K6:K80) -> 0 | L81: =SUM(L6:L80) -> 0 | ... O81: =SUM(O6:O80) -> 0
A83: ▶ CM1 (até 75 alunos)
A84: ID | B84: Nome Aluno | C84: Turma | D84: Propina | E84: Set | F84: Out | G84: Nov | H84: Dez | I84: Jan | J84: Fev | K84: Mar | L84: Abr | M84: Mai | N84: Jun | O84: Total | P84: Status | Q84: Obs.
A85: =IF('Controlo de Propinas'!A110="","",'Controlo de Propinas'!A110) -> CM1-01 | B85: =IF('Controlo de Propinas'!B110="","",'Controlo de Propinas'!B110) -> Crisber Uluwami António Cristovão De Sousa | C85: =IF('Controlo de Propinas'!C110="","",'Controlo de Propinas'!C110) -> CM1 | D85: =IF(C85="","",IF(OR(C85="Maternelle",C85="Maternelle P1",C85="Maternelle P2",C85="Maternelle P3"),170000,IF(C85="CM2",250000,IF(C85="4eme",260000,170000)))) -> 170000 | O85: =IF(B85="","",SUM(E85:N85)) -> 0 | P85: =IF(B85="","",IF(O85=0,"Pendente",IF(COUNTIF(E85:N85,">0")>=10,"Pago","Parcial"))) -> Pendente
A86: =IF('Controlo de Propinas'!A111="","",'Controlo de Propinas'!A111) -> CM1-02 | B86: =IF('Controlo de Propinas'!B111="","",'Controlo de Propinas'!B111) | C86: =IF('Controlo de Propinas'!C111="","",'Controlo de Propinas'!C111) -> CM1 | D86: =IF(C86="","",IF(OR(C86="Maternelle",C86="Maternelle P1",C86="Maternelle P2",C86="Maternelle P3"),170000,IF(C86="CM2",250000,IF(C86="4eme",260000,170000)))) -> 170000 | O86: =IF(B86="","",SUM(E86:N86)) | P86: =IF(B86="","",IF(O86=0,"Pendente",IF(COUNTIF(E86:N86,">0")>=10,"Pago","Parcial")))
A87: =IF('Controlo de Propinas'!A112="","",'Controlo de Propinas'!A112) | B87: =IF('Controlo de Propinas'!B112="","",'Controlo de Propinas'!B112) | C87: =IF('Controlo de Propinas'!C112="","",'Controlo de Propinas'!C112) -> CM1 | D87: =IF(C87="","",IF(OR(C87="Maternelle",C87="Maternelle P1",C87="Maternelle P2",C87="Maternelle P3"),170000,IF(C87="CM2",250000,IF(C87="4eme",260000,170000)))) -> 170000 | O87: =IF(B87="","",SUM(E87:N87)) | P87: =IF(B87="","",IF(O87=0,"Pendente",IF(COUNTIF(E87:N87,">0")>=10,"Pago","Parcial")))
A88: =IF('Controlo de Propinas'!A113="","",'Controlo de Propinas'!A113) | B88: =IF('Controlo de Propinas'!B113="","",'Controlo de Propinas'!B113) | C88: =IF('Controlo de Propinas'!C113="","",'Controlo de Propinas'!C113) -> CM1 | D88: =IF(C88="","",IF(OR(C88="Maternelle",C88="Maternelle P1",C88="Maternelle P2",C88="Maternelle P3"),170000,IF(C88="CM2",250000,IF(C88="4eme",260000,170000)))) -> 170000 | O88: =IF(B88="","",SUM(E88:N88)) | P88: =IF(B88="","",IF(O88=0,"Pendente",IF(COUNTIF(E88:N88,">0")>=10,"Pago","Parcial")))
A89: =IF('Controlo de Propinas'!A114="","",'Controlo de Propinas'!A114) | B89: =IF('Controlo de Propinas'!B114="","",'Controlo de Propinas'!B114) | C89: =IF('Controlo de Propinas'!C114="","",'Controlo de Propinas'!C114) -> CM1 | D89: =IF(C89="","",IF(OR(C89="Maternelle",C89="Maternelle P1",C89="Maternelle P2",C89="Maternelle P3"),170000,IF(C89="CM2",250000,IF(C89="4eme",260000,170000)))) -> 170000 | O89: =IF(B89="","",SUM(E89:N89)) | P89: =IF(B89="","",IF(O89=0,"Pendente",IF(COUNTIF(E89:N89,">0")>=10,"Pago","Parcial")))
A90: =IF('Controlo de Propinas'!A115="","",'Controlo de Propinas'!A115) | B90: =IF('Controlo de Propinas'!B115="","",'Controlo de Propinas'!B115) | C90: =IF('Controlo de Propinas'!C115="","",'Controlo de Propinas'!C115) -> CM1 | D90: =IF(C90="","",IF(OR(C90="Maternelle",C90="Maternelle P1",C90="Maternelle P2",C90="Maternelle P3"),170000,IF(C90="CM2",250000,IF(C90="4eme",260000,170000)))) -> 170000 | O90: =IF(B90="","",SUM(E90:N90)) | P90: =IF(B90="","",IF(O90=0,"Pendente",IF(COUNTIF(E90:N90,">0")>=10,"Pago","Parcial")))
A91: =IF('Controlo de Propinas'!A116="","",'Controlo de Propinas'!A116) | B91: =IF('Controlo de Propinas'!B116="","",'Controlo de Propinas'!B116) | C91: =IF('Controlo de Propinas'!C116="","",'Controlo de Propinas'!C116) -> CM1 | D91: =IF(C91="","",IF(OR(C91="Maternelle",C91="Maternelle P1",C91="Maternelle P2",C91="Maternelle P3"),170000,IF(C91="CM2",250000,IF(C91="4eme",260000,170000)))) -> 170000 | O91: =IF(B91="","",SUM(E91:N91)) | P91: =IF(B91="","",IF(O91=0,"Pendente",IF(COUNTIF(E91:N91,">0")>=10,"Pago","Parcial")))
A92: =IF('Controlo de Propinas'!A117="","",'Controlo de Propinas'!A117) | B92: =IF('Controlo de Propinas'!B117="","",'Controlo de Propinas'!B117) | C92: =IF('Controlo de Propinas'!C117="","",'Controlo de Propinas'!C117) -> CM1 | D92: =IF(C92="","",IF(OR(C92="Maternelle",C92="Maternelle P1",C92="Maternelle P2",C92="Maternelle P3"),170000,IF(C92="CM2",250000,IF(C92="4eme",260000,170000)))) -> 170000 | O92: =IF(B92="","",SUM(E92:N92)) | P92: =IF(B92="","",IF(O92=0,"Pendente",IF(COUNTIF(E92:N92,">0")>=10,"Pago","Parcial")))
A93: =IF('Controlo de Propinas'!A118="","",'Controlo de Propinas'!A118) | B93: =IF('Controlo de Propinas'!B118="","",'Controlo de Propinas'!B118) | C93: =IF('Controlo de Propinas'!C118="","",'Controlo de Propinas'!C118) -> CM1 | D93: =IF(C93="","",IF(OR(C93="Maternelle",C93="Maternelle P1",C93="Maternelle P2",C93="Maternelle P3"),170000,IF(C93="CM2",250000,IF(C93="4eme",260000,170000)))) -> 170000 | O93: =IF(B93="","",SUM(E93:N93)) | P93: =IF(B93="","",IF(O93=0,"Pendente",IF(COUNTIF(E93:N93,">0")>=10,"Pago","Parcial")))
A94: =IF('Controlo de Propinas'!A119="","",'Controlo de Propinas'!A119) | B94: =IF('Controlo de Propinas'!B119="","",'Controlo de Propinas'!B119) | C94: =IF('Controlo de Propinas'!C119="","",'Controlo de Propinas'!C119) -> CM1 | D94: =IF(C94="","",IF(OR(C94="Maternelle",C94="Maternelle P1",C94="Maternelle P2",C94="Maternelle P3"),170000,IF(C94="CM2",250000,IF(C94="4eme",260000,170000)))) -> 170000 | O94: =IF(B94="","",SUM(E94:N94)) | P94: =IF(B94="","",IF(O94=0,"Pendente",IF(COUNTIF(E94:N94,">0")>=10,"Pago","Parcial")))
A95: =IF('Controlo de Propinas'!A120="","",'Controlo de Propinas'!A120) | B95: =IF('Controlo de Propinas'!B120="","",'Controlo de Propinas'!B120) | C95: =IF('Controlo de Propinas'!C120="","",'Controlo de Propinas'!C120) -> CM1 | D95: =IF(C95="","",IF(OR(C95="Maternelle",C95="Maternelle P1",C95="Maternelle P2",C95="Maternelle P3"),170000,IF(C95="CM2",250000,IF(C95="4eme",260000,170000)))) -> 170000 | O95: =IF(B95="","",SUM(E95:N95)) | P95: =IF(B95="","",IF(O95=0,"Pendente",IF(COUNTIF(E95:N95,">0")>=10,"Pago","Parcial")))
A96: =IF('Controlo de Propinas'!A121="","",'Controlo de Propinas'!A121) | B96: =IF('Controlo de Propinas'!B121="","",'Controlo de Propinas'!B121) | C96: =IF('Controlo de Propinas'!C121="","",'Controlo de Propinas'!C121) -> CM1 | D96: =IF(C96="","",IF(OR(C96="Maternelle",C96="Maternelle P1",C96="Maternelle P2",C96="Maternelle P3"),170000,IF(C96="CM2",250000,IF(C96="4eme",260000,170000)))) -> 170000 | O96: =IF(B96="","",SUM(E96:N96)) | P96: =IF(B96="","",IF(O96=0,"Pendente",IF(COUNTIF(E96:N96,">0")>=10,"Pago","Parcial")))
... A98: =IF('Controlo de Propinas'!A123="","",'Controlo de Propinas'!A123) | B98: =IF('Controlo de Propinas'!B123="","",'Controlo de Propinas'!B123) | C98: =IF('Controlo de Propinas'!C123="","",'Controlo de Propinas'!C123) -> CM1 | D98: =IF(C98="","",IF(OR(C98="Maternelle",C98="Maternelle P1",C98="Maternelle P2",C98="Maternelle P3"),170000,IF(C98="CM2",250000,IF(C98="4eme",260000,170000)))) -> 170000 | O98: =IF(B98="","",SUM(E98:N98)) | P98: =IF(B98="","",IF(O98=0,"Pendente",IF(COUNTIF(E98:N98,">0")>=10,"Pago","Parcial")))
A99: Subtotal | B99: =COUNTIF(B85:B98,"?*")&" alunos" -> 1 alunos | O99: =SUM(O85:O98) -> 0
A101: ▶ CM2 (até 75 alunos)
A102: ID | B102: Nome Aluno | C102: Turma | D102: Propina | E102: Set | F102: Out | G102: Nov | H102: Dez | I102: Jan | J102: Fev | K102: Mar | L102: Abr | M102: Mai | N102: Jun | O102: Total | P102: Status | Q102: Obs.
A103: =IF('Controlo de Propinas'!A129="","",'Controlo de Propinas'!A129) -> CM2-01 | B103: =IF('Controlo de Propinas'!B129="","",'Controlo de Propinas'!B129) -> Kaila Abigail Katata da Silva | C103: =IF('Controlo de Propinas'!C129="","",'Controlo de Propinas'!C129) -> CM2 | D103: =IF(C85="","",IF(OR(C85="Maternelle",C85="Maternelle P1",C85="Maternelle P2",C85="Maternelle P3"),170000,IF(C85="CM2",250000,IF(C85="4eme",260000,170000)))) -> 170000 | E103: 0 | F103: 0 | G103: 0 | H103: 0 | I103: 0 | J103: 0 | K103: 0 | L103: 0 | M103: 0 | N103: 0 | O103: =IF(B85="","",SUM(E85:N85)) -> 0 | P103: =IF(B85="","",IF(O85=0,"Pendente",IF(O85<D85,"Parcial","Pago"))) -> Pendente
A104: =IF('Controlo de Propinas'!A130="","",'Controlo de Propinas'!A130) -> CM2-02 | B104: =IF('Controlo de Propinas'!B130="","",'Controlo de Propinas'!B130) -> Pedro Henriques Simão dos Santos | C104: =IF('Controlo de Propinas'!C130="","",'Controlo de Propinas'!C130) -> CM2 | D104: =IF(C86="","",IF(OR(C86="Maternelle",C86="Maternelle P1",C86="Maternelle P2",C86="Maternelle P3"),170000,IF(C86="CM2",250000,IF(C86="4eme",260000,170000)))) -> 170000 | E104: 0 | F104: 0 | G104: 0 | H104: 0 | I104: 0 | J104: 0 | K104: 0 | L104: 0 | M104: 0 | N104: 0 | O104: =IF(B86="","",SUM(E86:N86)) | P104: =IF(B86="","",IF(O86=0,"Pendente",IF(O86<D86,"Parcial","Pago")))
A105: =IF('Controlo de Propinas'!A131="","",'Controlo de Propinas'!A131) -> CM2-03 | B105: =IF('Controlo de Propinas'!B131="","",'Controlo de Propinas'!B131) -> Keane António Teixeira Correia de Azevedo | C105: =IF('Controlo de Propinas'!C131="","",'Controlo de Propinas'!C131) -> CM2 | D105: =IF(C87="","",IF(OR(C87="Maternelle",C87="Maternelle P1",C87="Maternelle P2",C87="Maternelle P3"),170000,IF(C87="CM2",250000,IF(C87="4eme",260000,170000)))) -> 170000 | E105: 0 | F105: 0 | G105: 0 | H105: 0 | I105: 0 | J105: 0 | K105: 0 | L105: 0 | M105: 0 | N105: 0 | O105: =IF(B87="","",SUM(E87:N87)) | P105: =IF(B87="","",IF(O87=0,"Pendente",IF(O87<D87,"Parcial","Pago")))
A106: =IF('Controlo de Propinas'!A132="","",'Controlo de Propinas'!A132) -> CM2-04 | B106: =IF('Controlo de Propinas'!B132="","",'Controlo de Propinas'!B132) -> Márcio Uzziel Francisco Venâncio | C106: =IF('Controlo de Propinas'!C132="","",'Controlo de Propinas'!C132) -> CM2 | D106: =IF(C88="","",IF(OR(C88="Maternelle",C88="Maternelle P1",C88="Maternelle P2",C88="Maternelle P3"),170000,IF(C88="CM2",250000,IF(C88="4eme",260000,170000)))) -> 170000 | E106: 0 | F106: 0 | G106: 0 | H106: 0 | I106: 0 | J106: 0 | K106: 0 | L106: 0 | M106: 0 | N106: 0 | O106: =IF(B88="","",SUM(E88:N88)) | P106: =IF(B88="","",IF(O88=0,"Pendente",IF(O88<D88,"Parcial","Pago")))
...

Sheet Cadastro de Alunos
A1: CADASTRO DE ALUNOS – 2026/2027
A2: Verde = puxado do Controlo de Propinas | Amarelo = preencher (Responsável, Contacto, Endereço, Alergias, Medicação)
A4: ▶ MATERNELLE
A5: ID | B5: Nome Aluno | C5: Turma | D5: Responsável | E5: Contacto | F5: Data Matrícula | G5: Propina Mensal | H5: Atividades | I5: Endereço | J5: Tem Alergias? | K5: Quais Alergias? | L5: Toma Medicação?
A6: =IF('Controlo de Propinas'!A6="","",'Controlo de Propinas'!A6) -> P1-01 | B6: =IF('Controlo de Propinas'!B6="","",'Controlo de Propinas'!B6) -> Hazail Epandi Calei da Costa | C6: =IF('Controlo de Propinas'!C6="","",'Controlo de Propinas'!C6) -> Maternelle | F6: =IF('Controlo de Propinas'!K6="","",'Controlo de Propinas'!K6) -> 46229 | G6: =IF(C6="","",IF(OR(C6="Maternelle",C6="Maternelle P1",C6="Maternelle P2",C6="Maternelle P3"),170000,IF(C6="CM2",250000,IF(C6="4eme",260000,170000)))) -> 170000
A7: =IF('Controlo de Propinas'!A7="","",'Controlo de Propinas'!A7) -> P1-02 | B7: =IF('Controlo de Propinas'!B7="","",'Controlo de Propinas'!B7) -> Erick Libânio Sebastião da Silva | C7: =IF('Controlo de Propinas'!C7="","",'Controlo de Propinas'!C7) -> Maternelle P1 | F7: =IF('Controlo de Propinas'!K7="","",'Controlo de Propinas'!K7) -> 46235 | G7: =IF(C7="","",IF(OR(C7="Maternelle",C7="Maternelle P1",C7="Maternelle P2",C7="Maternelle P3"),170000,IF(C7="CM2",250000,IF(C7="4eme",260000,170000)))) -> 170000
A8: =IF('Controlo de Propinas'!A8="","",'Controlo de Propinas'!A8) -> P2-03 | B8: =IF('Controlo de Propinas'!B8="","",'Controlo de Propinas'!B8) -> Eloa Marina Sebastião da Silva | C8: =IF('Controlo de Propinas'!C8="","",'Controlo de Propinas'!C8) -> Maternelle P2 | F8: =IF('Controlo de Propinas'!K8="","",'Controlo de Propinas'!K8) -> 46235 | G8: =IF(C8="","",IF(OR(C8="Maternelle",C8="Maternelle P1",C8="Maternelle P2",C8="Maternelle P3"),170000,IF(C8="CM2",250000,IF(C8="4eme",260000,170000)))) -> 170000
A9: =IF('Controlo de Propinas'!A9="","",'Controlo de Propinas'!A9) -> P2-04 | B9: =IF('Controlo de Propinas'!B9="","",'Controlo de Propinas'!B9) -> Ivander Trindade Bernardo Clementino | C9: =IF('Controlo de Propinas'!C9="","",'Controlo de Propinas'!C9) -> Maternelle P2 | F9: =IF('Controlo de Propinas'!K9="","",'Controlo de Propinas'!K9) -> 46240 | G9: =IF(C9="","",IF(OR(C9="Maternelle",C9="Maternelle P1",C9="Maternelle P2",C9="Maternelle P3"),170000,IF(C9="CM2",250000,IF(C9="4eme",260000,170000)))) -> 170000
A10: =IF('Controlo de Propinas'!A10="","",'Controlo de Propinas'!A10) -> P3-05 | B10: =IF('Controlo de Propinas'!B10="","",'Controlo de Propinas'!B10) -> Gael Hanji Ventura Quimbundo | C10: =IF('Controlo de Propinas'!C10="","",'Controlo de Propinas'!C10) -> Maternelle P3 | F10: =IF('Controlo de Propinas'!K10="","",'Controlo de Propinas'!K10) -> 46237 | G10: =IF(C10="","",IF(OR(C10="Maternelle",C10="Maternelle P1",C10="Maternelle P2",C10="Maternelle P3"),170000,IF(C10="CM2",250000,IF(C10="4eme",260000,170000)))) -> 170000
A11: =IF('Controlo de Propinas'!A11="","",'Controlo de Propinas'!A11) -> P3-06 | B11: =IF('Controlo de Propinas'!B11="","",'Controlo de Propinas'!B11) -> Ivanna Chayane Bernardo Clementino | C11: =IF('Controlo de Propinas'!C11="","",'Controlo de Propinas'!C11) -> Maternelle P3 | F11: =IF('Controlo de Propinas'!K11="","",'Controlo de Propinas'!K11) -> 46240 | G11: =IF(C11="","",IF(OR(C11="Maternelle",C11="Maternelle P1",C11="Maternelle P2",C11="Maternelle P3"),170000,IF(C11="CM2",250000,IF(C11="4eme",260000,170000)))) -> 170000
A12: =IF('Controlo de Propinas'!A12="","",'Controlo de Propinas'!A12) -> P3-07 | B12: =IF('Controlo de Propinas'!B12="","",'Controlo de Propinas'!B12) -> Wendy Aryanne Chimuco Sabino | C12: =IF('Controlo de Propinas'!C12="","",'Controlo de Propinas'!C12) -> Maternelle P3 | F12: =IF('Controlo de Propinas'!K12="","",'Controlo de Propinas'!K12) -> 46232 | G12: =IF(C12="","",IF(OR(C12="Maternelle",C12="Maternelle P1",C12="Maternelle P2",C12="Maternelle P3"),170000,IF(C12="CM2",250000,IF(C12="4eme",260000,170000)))) -> 170000
A13: =IF('Controlo de Propinas'!A13="","",'Controlo de Propinas'!A13) -> P1-08 | B13: =IF('Controlo de Propinas'!B13="","",'Controlo de Propinas'!B13) -> Kesane Aimé Teixeira Correia de Azevedo | C13: =IF('Controlo de Propinas'!C13="","",'Controlo de Propinas'!C13) -> Maternelle P1 | F13: =IF('Controlo de Propinas'!K13="","",'Controlo de Propinas'!K13) -> 46255 | G13: =IF(C13="","",IF(OR(C13="Maternelle",C13="Maternelle P1",C13="Maternelle P2",C13="Maternelle P3"),170000,IF(C13="CM2",250000,IF(C13="4eme",260000,170000)))) -> 170000
A14: =IF('Controlo de Propinas'!A14="","",'Controlo de Propinas'!A14) -> P3-09 | B14: =IF('Controlo de Propinas'!B14="","",'Controlo de Propinas'!B14) -> Kuami Hazael Francisco Venâncio | C14: =IF('Controlo de Propinas'!C14="","",'Controlo de Propinas'!C14) -> Maternelle P3 | F14: =IF('Controlo de Propinas'!K14="","",'Controlo de Propinas'!K14) -> 46245 | G14: =IF(C14="","",IF(OR(C14="Maternelle",C14="Maternelle P1",C14="Maternelle P2",C14="Maternelle P3"),170000,IF(C14="CM2",250000,IF(C14="4eme",260000,170000)))) -> 170000
A15: =IF('Controlo de Propinas'!A15="","",'Controlo de Propinas'!A15) | B15: =IF('Controlo de Propinas'!B15="","",'Controlo de Propinas'!B15) | C15: =IF('Controlo de Propinas'!C15="","",'Controlo de Propinas'!C15) | F15: =IF('Controlo de Propinas'!K15="","",'Controlo de Propinas'!K15) | G15: =IF(C15="","",IF(OR(C15="Maternelle",C15="Maternelle P1",C15="Maternelle P2",C15="Maternelle P3"),170000,IF(C15="CM2",250000,IF(C15="4eme",260000,170000))))
A16: =IF('Controlo de Propinas'!A16="","",'Controlo de Propinas'!A16) | B16: =IF('Controlo de Propinas'!B16="","",'Controlo de Propinas'!B16) | C16: =IF('Controlo de Propinas'!C16="","",'Controlo de Propinas'!C16) | F16: =IF('Controlo de Propinas'!K16="","",'Controlo de Propinas'!K16) | G16: =IF(C16="","",IF(OR(C16="Maternelle",C16="Maternelle P1",C16="Maternelle P2",C16="Maternelle P3"),170000,IF(C16="CM2",250000,IF(C16="4eme",260000,170000))))
A17: =IF('Controlo de Propinas'!A17="","",'Controlo de Propinas'!A17) | B17: =IF('Controlo de Propinas'!B17="","",'Controlo de Propinas'!B17) | C17: =IF('Controlo de Propinas'!C17="","",'Controlo de Propinas'!C17) | F17: =IF('Controlo de Propinas'!K17="","",'Controlo de Propinas'!K17) | G17: =IF(C17="","",IF(OR(C17="Maternelle",C17="Maternelle P1",C17="Maternelle P2",C17="Maternelle P3"),170000,IF(C17="CM2",250000,IF(C17="4eme",260000,170000))))
... A105: =IF('Controlo de Propinas'!A105="","",'Controlo de Propinas'!A105) | B105: =IF('Controlo de Propinas'!B105="","",'Controlo de Propinas'!B105) | C105: =IF('Controlo de Propinas'!C105="","",'Controlo de Propinas'!C105) | F105: =IF('Controlo de Propinas'!K105="","",'Controlo de Propinas'!K105) | G105: =IF(C105="","",IF(OR(C105="Maternelle",C105="Maternelle P1",C105="Maternelle P2",C105="Maternelle P3"),170000,IF(C105="CM2",250000,IF(C105="4eme",260000,170000))))
A106: Subtotal | B106: =COUNTIF(B6:B105,"?*")&" alunos" -> 9 alunos
A108: ▶ CM1
A109: ID | B109: Nome Aluno | C109: Turma | D109: Responsável | E109: Contacto | F109: Data Matrícula | G109: Propina Mensal | H109: Atividades | I109: Endereço | J109: Tem Alergias? | K109: Quais Alergias? | L109: Toma Medicação?
A110: =IF('Controlo de Propinas'!A110="","",'Controlo de Propinas'!A110) -> CM1-01 | B110: =IF('Controlo de Propinas'!B110="","",'Controlo de Propinas'!B110) -> Crisber Uluwami António Cristovão De Sousa | C110: =IF('Controlo de Propinas'!C110="","",'Controlo de Propinas'!C110) -> CM1
A111: =IF('Controlo de Propinas'!A111="","",'Controlo de Propinas'!A111) -> CM1-02 | B111: =IF('Controlo de Propinas'!B111="","",'Controlo de Propinas'!B111) | C111: =IF('Controlo de Propinas'!C111="","",'Controlo de Propinas'!C111) -> CM1
A112: =IF('Controlo de Propinas'!A112="","",'Controlo de Propinas'!A112) | B112: =IF('Controlo de Propinas'!B112="","",'Controlo de Propinas'!B112) | C112: =IF('Controlo de Propinas'!C112="","",'Controlo de Propinas'!C112) -> CM1
A113: =IF('Controlo de Propinas'!A113="","",'Controlo de Propinas'!A113) | B113: =IF('Controlo de Propinas'!B113="","",'Controlo de Propinas'!B113) | C113: =IF('Controlo de Propinas'!C113="","",'Controlo de Propinas'!C113) -> CM1
A114: =IF('Controlo de Propinas'!A114="","",'Controlo de Propinas'!A114) | B114: =IF('Controlo de Propinas'!B114="","",'Controlo de Propinas'!B114) | C114: =IF('Controlo de Propinas'!C114="","",'Controlo de Propinas'!C114) -> CM1
A115: =IF('Controlo de Propinas'!A115="","",'Controlo de Propinas'!A115) | B115: =IF('Controlo de Propinas'!B115="","",'Controlo de Propinas'!B115) | C115: =IF('Controlo de Propinas'!C115="","",'Controlo de Propinas'!C115) -> CM1
A116: =IF('Controlo de Propinas'!A116="","",'Controlo de Propinas'!A116) | B116: =IF('Controlo de Propinas'!B116="","",'Controlo de Propinas'!B116) | C116: =IF('Controlo de Propinas'!C116="","",'Controlo de Propinas'!C116) -> CM1
A117: =IF('Controlo de Propinas'!A117="","",'Controlo de Propinas'!A117) | B117: =IF('Controlo de Propinas'!B117="","",'Controlo de Propinas'!B117) | C117: =IF('Controlo de Propinas'!C117="","",'Controlo de Propinas'!C117) -> CM1
A118: =IF('Controlo de Propinas'!A118="","",'Controlo de Propinas'!A118) | B118: =IF('Controlo de Propinas'!B118="","",'Controlo de Propinas'!B118) | C118: =IF('Controlo de Propinas'!C118="","",'Controlo de Propinas'!C118) -> CM1
A119: =IF('Controlo de Propinas'!A119="","",'Controlo de Propinas'!A119) | B119: =IF('Controlo de Propinas'!B119="","",'Controlo de Propinas'!B119) | C119: =IF('Controlo de Propinas'!C119="","",'Controlo de Propinas'!C119) -> CM1
A120: =IF('Controlo de Propinas'!A120="","",'Controlo de Propinas'!A120) | B120: =IF('Controlo de Propinas'!B120="","",'Controlo de Propinas'!B120) | C120: =IF('Controlo de Propinas'!C120="","",'Controlo de Propinas'!C120) -> CM1
A121: =IF('Controlo de Propinas'!A121="","",'Controlo de Propinas'!A121) | B121: =IF('Controlo de Propinas'!B121="","",'Controlo de Propinas'!B121) | C121: =IF('Controlo de Propinas'!C121="","",'Controlo de Propinas'!C121) -> CM1
... A123: =IF('Controlo de Propinas'!A123="","",'Controlo de Propinas'!A123) | B123: =IF('Controlo de Propinas'!B123="","",'Controlo de Propinas'!B123) | C123: =IF('Controlo de Propinas'!C123="","",'Controlo de Propinas'!C123) -> CM1
A124: Subtotal | B124: =COUNTIF(B110:B123,"?*")&" alunos" -> 1 alunos
A126: ▶ CM2
A127: ID | B127: Nome Aluno | C127: Turma | D127: Responsável | E127: Contacto | F127: Data Matrícula | G127: Propina Mensal | H127: Atividades | I127: Endereço | J127: Tem Alergias? | K127: Quais Alergias? | L127: Toma Medicação?
A128: =IF('Controlo de Propinas'!A129="","",'Controlo de Propinas'!A129) -> CM2-01 | B128: =IF('Controlo de Propinas'!B129="","",'Controlo de Propinas'!B129) -> Kaila Abigail Katata da Silva | C128: =IF('Controlo de Propinas'!C129="","",'Controlo de Propinas'!C129) -> CM2 | F128: =IF('Controlo de Propinas'!K129="","",'Controlo de Propinas'!K129) -> 46230 | G128: =IF(C110="","",IF(OR(C110="Maternelle",C110="Maternelle P1",C110="Maternelle P2",C110="Maternelle P3"),170000,IF(C110="CM2",250000,IF(C110="4eme",260000,170000)))) -> 170000
A129: =IF('Controlo de Propinas'!A130="","",'Controlo de Propinas'!A130) -> CM2-02 | B129: =IF('Controlo de Propinas'!B130="","",'Controlo de Propinas'!B130) -> Pedro Henriques Simão dos Santos | C129: =IF('Controlo de Propinas'!C130="","",'Controlo de Propinas'!C130) -> CM2 | F129: =IF('Controlo de Propinas'!K130="","",'Controlo de Propinas'!K130) -> 46229 | G129: =IF(C111="","",IF(OR(C111="Maternelle",C111="Maternelle P1",C111="Maternelle P2",C111="Maternelle P3"),170000,IF(C111="CM2",250000,IF(C111="4eme",260000,170000)))) -> 170000
A130: =IF('Controlo de Propinas'!A131="","",'Controlo de Propinas'!A131) -> CM2-03 | B130: =IF('Controlo de Propinas'!B131="","",'Controlo de Propinas'!B131) -> Keane António Teixeira Correia de Azevedo | C130: =IF('Controlo de Propinas'!C131="","",'Controlo de Propinas'!C131) -> CM2 | F130: =IF('Controlo de Propinas'!K131="","",'Controlo de Propinas'!K131) -> 46239 | G130: =IF(C112="","",IF(OR(C112="Maternelle",C112="Maternelle P1",C112="Maternelle P2",C112="Maternelle P3"),170000,IF(C112="CM2",250000,IF(C112="4eme",260000,170000)))) -> 170000
A131: =IF('Controlo de Propinas'!A132="","",'Controlo de Propinas'!A132) -> CM2-04 | B131: =IF('Controlo de Propinas'!B132="","",'Controlo de Propinas'!B132) -> Márcio Uzziel Francisco Venâncio | C131: =IF('Controlo de Propinas'!C132="","",'Controlo de Propinas'!C132) -> CM2 | F131: =IF('Controlo de Propinas'!K132="","",'Controlo de Propinas'!K132) -> 46245 | G131: =IF(C113="","",IF(OR(C113="Maternelle",C113="Maternelle P1",C113="Maternelle P2",C113="Maternelle P3"),170000,IF(C113="CM2",250000,IF(C113="4eme",260000,170000)))) -> 170000
...

Sheet Controlo de Manuais
A1: CONTROLO DE MANUAIS ESCOLARES – 2026/2027
A2: Amarelo = input manual. Verde = calculado. Ligado ao Controlo de Propinas (coluna Manuais). Organize por turma.
A4: ID | B4: Nome Aluno | C4: Turma | D4: Valor Manuais (KZ) | E4: Comprou? | F4: Data Compra | G4: Forma Pagamento | H4: Nº Recibo | I4: Observações | J4: Status | K4: Valor Recebido | L4: Pendente
A5: MATERNELLE
A6: MAT-01 | B6: ='Controlo de Propinas'!B6 -> Hazail Epandi Calei da Costa | C6: ='Controlo de Propinas'!C6 -> Maternelle | D6: =IF('Controlo de Propinas'!E6="","",'Controlo de Propinas'!E6) | E6: Não | J6: =IF(E6="Sim","Pago",IF(OR(D6=0,D6=""),"N/A","Pendente")) -> N/A | K6: =IF(E6="Sim",IF(D6="",0,D6),0) -> 0 | L6: =IF(E6="Sim",0,IF(D6="",0,D6)) -> 0
A7: MAT-02 | B7: ='Controlo de Propinas'!B7 -> Erick Libânio Sebastião da Silva | C7: ='Controlo de Propinas'!C7 -> Maternelle P1 | D7: =IF('Controlo de Propinas'!E7="","",'Controlo de Propinas'!E7) | E7: Não | J7: =IF(E7="Sim","Pago",IF(OR(D7=0,D7=""),"N/A","Pendente")) -> N/A | K7: =IF(E7="Sim",IF(D7="",0,D7),0) -> 0 | L7: =IF(E7="Sim",0,IF(D7="",0,D7)) -> 0
A8: MAT-03 | B8: ='Controlo de Propinas'!B8 -> Eloa Marina Sebastião da Silva | C8: ='Controlo de Propinas'!C8 -> Maternelle P2 | D8: =IF('Controlo de Propinas'!E8="","",'Controlo de Propinas'!E8) | E8: Não | J8: =IF(E8="Sim","Pago",IF(OR(D8=0,D8=""),"N/A","Pendente")) -> N/A | K8: =IF(E8="Sim",IF(D8="",0,D8),0) -> 0 | L8: =IF(E8="Sim",0,IF(D8="",0,D8)) -> 0
A9: MAT-04 | B9: ='Controlo de Propinas'!B9 -> Ivander Trindade Bernardo Clementino | C9: ='Controlo de Propinas'!C9 -> Maternelle P2 | D9: =IF('Controlo de Propinas'!E9="","",'Controlo de Propinas'!E9) | E9: Não | J9: =IF(E9="Sim","Pago",IF(OR(D9=0,D9=""),"N/A","Pendente")) -> N/A | K9: =IF(E9="Sim",IF(D9="",0,D9),0) -> 0 | L9: =IF(E9="Sim",0,IF(D9="",0,D9)) -> 0
A10: MAT-05 | B10: ='Controlo de Propinas'!B10 -> Gael Hanji Ventura Quimbundo | C10: ='Controlo de Propinas'!C10 -> Maternelle P3 | D10: =IF('Controlo de Propinas'!E10="","",'Controlo de Propinas'!E10) | E10: Não | J10: =IF(E10="Sim","Pago",IF(OR(D10=0,D10=""),"N/A","Pendente")) -> N/A | K10: =IF(E10="Sim",IF(D10="",0,D10),0) -> 0 | L10: =IF(E10="Sim",0,IF(D10="",0,D10)) -> 0
A11: MAT-06 | B11: ='Controlo de Propinas'!B11 -> Ivanna Chayane Bernardo Clementino | C11: ='Controlo de Propinas'!C11 -> Maternelle P3 | D11: =IF('Controlo de Propinas'!E11="","",'Controlo de Propinas'!E11) | E11: Não | J11: =IF(E11="Sim","Pago",IF(OR(D11=0,D11=""),"N/A","Pendente")) -> N/A | K11: =IF(E11="Sim",IF(D11="",0,D11),0) -> 0 | L11: =IF(E11="Sim",0,IF(D11="",0,D11)) -> 0
A12: MAT-07 | B12: ='Controlo de Propinas'!B12 -> Wendy Aryanne Chimuco Sabino | C12: ='Controlo de Propinas'!C12 -> Maternelle P3 | D12: =IF('Controlo de Propinas'!E12="","",'Controlo de Propinas'!E12) | E12: Não | J12: =IF(E12="Sim","Pago",IF(OR(D12=0,D12=""),"N/A","Pendente")) -> N/A | K12: =IF(E12="Sim",IF(D12="",0,D12),0) -> 0 | L12: =IF(E12="Sim",0,IF(D12="",0,D12)) -> 0
A13: MAT-08 | B13: ='Controlo de Propinas'!B13 -> Kesane Aimé Teixeira Correia de Azevedo | C13: ='Controlo de Propinas'!C13 -> Maternelle P1 | D13: =IF('Controlo de Propinas'!E13="","",'Controlo de Propinas'!E13) | E13: Não | J13: =IF(E13="Sim","Pago",IF(OR(D13=0,D13=""),"N/A","Pendente")) -> N/A | K13: =IF(E13="Sim",IF(D13="",0,D13),0) -> 0 | L13: =IF(E13="Sim",0,IF(D13="",0,D13)) -> 0
A14: MAT-09 | B14: ='Controlo de Propinas'!B14 -> Kuami Hazael Francisco Venâncio | C14: ='Controlo de Propinas'!C14 -> Maternelle P3 | D14: =IF('Controlo de Propinas'!E14="","",'Controlo de Propinas'!E14) | E14: Não | J14: =IF(E14="Sim","Pago",IF(OR(D14=0,D14=""),"N/A","Pendente")) -> N/A | K14: =IF(E14="Sim",IF(D14="",0,D14),0) -> 0 | L14: =IF(E14="Sim",0,IF(D14="",0,D14)) -> 0
J15: =IF(E15="Sim","Pago",IF(D15=0,"N/A","Pendente")) -> N/A
A17: Subtotal | B17: =COUNTA(B6:B14)&" alunos" -> 9 alunos | D17: =SUM(D6:D14) -> 0 | K17: =SUM(K6:K14) -> 0 | L17: =SUM(L6:L14) -> 0
A19: CM2
A20: ID | B20: Nome Aluno | C20: Turma | D20: Valor Manuais (KZ) | E20: Comprou? | F20: Data Compra | G20: Forma Pagamento | H20: Nº Recibo | I20: Observações | J20: Status | K20: Valor Recebido | L20: Pendente
A21: CM2-01 | B21: ='Controlo de Propinas'!B110 -> Crisber Uluwami António Cristovão De Sousa | C21: ='Controlo de Propinas'!C110 -> CM1 | D21: =IF('Controlo de Propinas'!E110="","",'Controlo de Propinas'!E110) | E21: Sim | F21: 46230 | G21: Cartão Multicaixa | J21: =IF(E21="Sim","Pago",IF(OR(D21=0,D21=""),"N/A","Pendente")) -> Pago | K21: =IF(E21="Sim",IF(D21="",0,D21),0) -> 0 | L21: =IF(E21="Sim",0,IF(D21="",0,D21)) -> 0
A22: CM2-02 | B22: ='Controlo de Propinas'!B111 -> 0 | C22: ='Controlo de Propinas'!C111 -> CM1 | D22: =IF('Controlo de Propinas'!E111="","",'Controlo de Propinas'!E111) | E22: Sim | F22: 46167 | G22: Cartão Multicaixa | J22: =IF(E22="Sim","Pago",IF(OR(D22=0,D22=""),"N/A","Pendente")) -> Pago | K22: =IF(E22="Sim",IF(D22="",0,D22),0) -> 0 | L22: =IF(E22="Sim",0,IF(D22="",0,D22)) -> 0
A23: CM2-03 | B23: ='Controlo de Propinas'!B112 -> 0 | C23: ='Controlo de Propinas'!C112 -> CM1 | D23: =IF('Controlo de Propinas'!E112="","",'Controlo de Propinas'!E112) | E23: Não | J23: =IF(E23="Sim","Pago",IF(OR(D23=0,D23=""),"N/A","Pendente")) -> N/A | K23: =IF(E23="Sim",IF(D23="",0,D23),0) -> 0 | L23: =IF(E23="Sim",0,IF(D23="",0,D23)) -> 0
A24: CM2-04 | B24: ='Controlo de Propinas'!B113 -> 0 | C24: ='Controlo de Propinas'!C113 -> CM1 | D24: =IF('Controlo de Propinas'!E113="","",'Controlo de Propinas'!E113) | E24: Não | J24: =IF(E24="Sim","Pago",IF(OR(D24=0,D24=""),"N/A","Pendente")) -> N/A | K24: =IF(E24="Sim",IF(D24="",0,D24),0) -> 0 | L24: =IF(E24="Sim",0,IF(D24="",0,D24)) -> 0
A26: Subtotal | B26: =COUNTA(B21:B24)&" alunos" -> 4 alunos | D26: =SUM(D21:D24) -> 0 | K26: =SUM(K21:K24) -> 0 | L26: =SUM(L21:L24) -> 0
A28: 4EME
A29: ID | B29: Nome Aluno | C29: Turma | D29: Valor Manuais (KZ) | E29: Comprou? | F29: Data Compra | G29: Forma Pagamento | H29: Nº Recibo | I29: Observações | J29: Status | K29: Valor Recebido | L29: Pendente
A30: 4E-01 | B30: ='Controlo de Propinas'!B174 -> 0 | C30: ='Controlo de Propinas'!C174 -> CM2 | D30: =IF('Controlo de Propinas'!E174="","",'Controlo de Propinas'!E174) | E30: Não | J30: =IF(E30="Sim","Pago",IF(OR(D30=0,D30=""),"N/A","Pendente")) -> N/A | K30: =IF(E30="Sim",IF(D30="",0,D30),0) -> 0 | L30: =IF(E30="Sim",0,IF(D30="",0,D30)) -> 0
A33: Subtotal | B33: =COUNTA(B30:B30)&" alunos" -> 1 alunos | D33: =SUM(D30:D30) -> 0 | K33: =SUM(K30:K30) -> 0 | L33: =SUM(L30:L30) -> 0
A35: TOTAL GERAL | B35: =COUNTA(B6:B14)+COUNTA(B21:B24)+COUNTA(B30:B30)&" alunos" -> 14 alunos | D35: =D17+D26+D33 -> 0 | K35: =K17+K26+K33 -> 0 | L35: =L17+L26+L33 -> 0
A37: NOTA: Preencha "Comprou?" com Sim/Não. Valor Manuais pode ser atualizado manualmente ou sincronizado com Controlo de Propinas. Status, Valor Recebido e Pendente são automáticos.
A38: Ecole Consulaire du Congo (Brazzaville) de Luanda • Controlo de Manuais por Turma
A40: ▶ PROFESSORES E FUNCIONÁRIOS – VENDA DE MANUAIS (tabela independente dos alunos)
A41: Registo de compras de manuais por professores e funcionários da escola. Não está ligado ao Controlo de Propinas. Amarelo = preencher | Verde = calculado.
A43: Nº | B43: ID / Código | C43: Nome | D43: Categoria | E43: Função | F43: Valor Manuais (KZ) | G43: Comprou? | H43: Data Compra | I43: Forma Pagamento | J43: Nº Recibo | K43: Observações | L43: Status
A44: =IF(C44="","",TEXT(COUNTA($C$44:C44),"000")) -> 001 | B44: FUNC-001 | C44: Leia | D44: Secretaria | E44: Empregada Limpeza | F44: 2000 | G44: Não | H44: 46246 | I44: Transferência | L44: =IF(C44="","",IF(G44="Sim","Pago",IF(OR(F44=0,F44=""),"N/A","Pendente"))) -> Pendente
A45: =IF(C45="","",TEXT(COUNTA($C$44:C45),"000")) | L45: =IF(C45="","",IF(G45="Sim","Pago",IF(OR(F45=0,F45=""),"N/A","Pendente")))
A46: =IF(C46="","",TEXT(COUNTA($C$44:C46),"000")) | L46: =IF(C46="","",IF(G46="Sim","Pago",IF(OR(F46=0,F46=""),"N/A","Pendente")))
A47: =IF(C47="","",TEXT(COUNTA($C$44:C47),"000")) | L47: =IF(C47="","",IF(G47="Sim","Pago",IF(OR(F47=0,F47=""),"N/A","Pendente")))
A48: =IF(C48="","",TEXT(COUNTA($C$44:C48),"000")) | L48: =IF(C48="","",IF(G48="Sim","Pago",IF(OR(F48=0,F48=""),"N/A","Pendente")))
A49: =IF(C49="","",TEXT(COUNTA($C$44:C49),"000")) | L49: =IF(C49="","",IF(G49="Sim","Pago",IF(OR(F49=0,F49=""),"N/A","Pendente")))
A50: =IF(C50="","",TEXT(COUNTA($C$44:C50),"000")) | L50: =IF(C50="","",IF(G50="Sim","Pago",IF(OR(F50=0,F50=""),"N/A","Pendente")))
A51: =IF(C51="","",TEXT(COUNTA($C$44:C51),"000")) | L51: =IF(C51="","",IF(G51="Sim","Pago",IF(OR(F51=0,F51=""),"N/A","Pendente")))
...

Sheet Lançamentos Contábeis
A1: LANÇAMENTOS CONTÁBEIS
A2: Gerado automaticamente a partir dos pagamentos
A4: INSCRIÇÕES / MATRICULAS
A5: Data | B5: Debito | C5: Credito | D5: Descricao | E5: Valor | F5: ID | G5: Aluno | H5: Ref.
A6: ='Controlo de Propinas'!K4 -> 0 | B6: 41 | C6: 81 | D6: ="Inscricao - "&'Controlo de Propinas'!B4 -> Inscricao - | E6: ='Controlo de Propinas'!N4 -> 0 | F6: ='Controlo de Propinas'!A4 -> ▶ MATERNELLE | G6: ='Controlo de Propinas'!B4 -> 0 | H6: Inscricao
A7: ='Controlo de Propinas'!K5 -> Data Pag. | B7: 41 | C7: 81 | D7: ="Inscricao - "&'Controlo de Propinas'!B5 -> Inscricao - Nome Aluno | E7: ='Controlo de Propinas'!N5 -> Valor c/ Desc. | F7: ='Controlo de Propinas'!A5 -> ID | G7: ='Controlo de Propinas'!B5 -> Nome Aluno | H7: Inscricao
A8: ='Controlo de Propinas'!K6 -> 46229 | B8: 41 | C8: 81 | D8: ="Inscricao - "&'Controlo de Propinas'!B6 -> Inscricao - Hazail Epandi Calei da Costa | E8: ='Controlo de Propinas'!N6 -> 162000 | F8: ='Controlo de Propinas'!A6 -> P1-01 | G8: ='Controlo de Propinas'!B6 -> Hazail Epandi Calei da Costa | H8: Inscricao
A9: ='Controlo de Propinas'!K7 -> 46235 | B9: 41 | C9: 81 | D9: ="Inscricao - "&'Controlo de Propinas'!B7 -> Inscricao - Erick Libânio Sebastião da Silva | E9: ='Controlo de Propinas'!N7 -> 180000 | F9: ='Controlo de Propinas'!A7 -> P1-02 | G9: ='Controlo de Propinas'!B7 -> Erick Libânio Sebastião da Silva | H9: Inscricao
A10: ='Controlo de Propinas'!K8 -> 46235 | B10: 41 | C10: 81 | D10: ="Inscricao - "&'Controlo de Propinas'!B8 -> Inscricao - Eloa Marina Sebastião da Silva | E10: ='Controlo de Propinas'!N8 -> 180000 | F10: ='Controlo de Propinas'!A8 -> P2-03 | G10: ='Controlo de Propinas'!B8 -> Eloa Marina Sebastião da Silva | H10: Inscricao
A11: ='Controlo de Propinas'!K9 -> 46240 | B11: 41 | C11: 81 | D11: ="Inscricao - "&'Controlo de Propinas'!B9 -> Inscricao - Ivander Trindade Bernardo Clementino | E11: ='Controlo de Propinas'!N9 -> 180000 | F11: ='Controlo de Propinas'!A9 -> P2-04 | G11: ='Controlo de Propinas'!B9 -> Ivander Trindade Bernardo Clementino | H11: Inscricao
A12: ='Controlo de Propinas'!K10 -> 46237 | B12: 41 | C12: 81 | D12: ="Inscricao - "&'Controlo de Propinas'!B10 -> Inscricao - Gael Hanji Ventura Quimbundo | E12: ='Controlo de Propinas'!N10 -> 180000 | F12: ='Controlo de Propinas'!A10 -> P3-05 | G12: ='Controlo de Propinas'!B10 -> Gael Hanji Ventura Quimbundo | H12: Inscricao
A13: ='Controlo de Propinas'!K11 -> 46240 | B13: 41 | C13: 81 | D13: ="Inscricao - "&'Controlo de Propinas'!B11 -> Inscricao - Ivanna Chayane Bernardo Clementino | E13: ='Controlo de Propinas'!N11 -> 180000 | F13: ='Controlo de Propinas'!A11 -> P3-06 | G13: ='Controlo de Propinas'!B11 -> Ivanna Chayane Bernardo Clementino | H13: Inscricao
A14: ='Controlo de Propinas'!K12 -> 46232 | B14: 41 | C14: 81 | D14: ="Inscricao - "&'Controlo de Propinas'!B12 -> Inscricao - Wendy Aryanne Chimuco Sabino | E14: ='Controlo de Propinas'!N12 -> 350000 | F14: ='Controlo de Propinas'!A12 -> P3-07 | G14: ='Controlo de Propinas'!B12 -> Wendy Aryanne Chimuco Sabino | H14: Inscricao
A15: ='Controlo de Propinas'!K13 -> 46255 | B15: 41 | C15: 81 | D15: ="Inscricao - "&'Controlo de Propinas'!B13 -> Inscricao - Kesane Aimé Teixeira Correia de Azevedo | E15: ='Controlo de Propinas'!N13 -> 150000 | F15: ='Controlo de Propinas'!A13 -> P1-08 | G15: ='Controlo de Propinas'!B13 -> Kesane Aimé Teixeira Correia de Azevedo | H15: Inscricao
A16: ='Controlo de Propinas'!K14 -> 46245 | B16: 41 | C16: 81 | D16: ="Inscricao - "&'Controlo de Propinas'!B14 -> Inscricao - Kuami Hazael Francisco Venâncio | E16: ='Controlo de Propinas'!N14 -> 150000 | F16: ='Controlo de Propinas'!A14 -> P3-09 | G16: ='Controlo de Propinas'!B14 -> Kuami Hazael Francisco Venâncio | H16: Inscricao
A17: ='Controlo de Propinas'!K15 -> 0 | B17: 41 | C17: 81 | D17: ="Inscricao - "&'Controlo de Propinas'!B15 -> Inscricao - | E17: ='Controlo de Propinas'!N15 | F17: ='Controlo de Propinas'!A15 -> 0 | G17: ='Controlo de Propinas'!B15 -> 0 | H17: Inscricao
... A19: ='Controlo de Propinas'!K17 -> 0 | B19: 41 | C19: 81 | D19: ="Inscricao - "&'Controlo de Propinas'!B17 -> Inscricao - | E19: ='Controlo de Propinas'!N17 | F19: ='Controlo de Propinas'!A17 -> 0 | G19: ='Controlo de Propinas'!B17 -> 0 | H19: Inscricao
D21: TOTAL INSCRICOES | E21: =SUM(E6:E19) -> 1712000
A23: MENSALIDADES (Setembro)
A24: Data | B24: Debito | C24: Credito | D24: Descricao | E24: Valor | F24: ID | G24: Aluno | H24: Ref.
A25: 46270 | B25: 41 | C25: 81 | D25: ="Propina - "&Mensalidades!B6&" Set/26" -> Propina - Hazail Epandi Calei da Costa Set/26 | E25: =IF(Mensalidades!E6>0,Mensalidades!E6,"") | F25: =Mensalidades!A6 -> P1-01 | G25: =Mensalidades!B6 -> Hazail Epandi Calei da Costa | H25: Propina
A26: 46270 | B26: 41 | C26: 81 | D26: ="Propina - "&Mensalidades!B7&" Set/26" -> Propina - Erick Libânio Sebastião da Silva Set/26 | E26: =IF(Mensalidades!E7>0,Mensalidades!E7,"") | F26: =Mensalidades!A7 -> P1-02 | G26: =Mensalidades!B7 -> Erick Libânio Sebastião da Silva | H26: Propina
A27: 46270 | B27: 41 | C27: 81 | D27: ="Propina - "&Mensalidades!B8&" Set/26" -> Propina - Eloa Marina Sebastião da Silva Set/26 | E27: =IF(Mensalidades!E8>0,Mensalidades!E8,"") | F27: =Mensalidades!A8 -> P2-03 | G27: =Mensalidades!B8 -> Eloa Marina Sebastião da Silva | H27: Propina
A28: 46270 | B28: 41 | C28: 81 | D28: ="Propina - "&Mensalidades!B9&" Set/26" -> Propina - Ivander Trindade Bernardo Clementino Set/26 | E28: =IF(Mensalidades!E9>0,Mensalidades!E9,"") | F28: =Mensalidades!A9 -> P2-04 | G28: =Mensalidades!B9 -> Ivander Trindade Bernardo Clementino | H28: Propina
A29: 46270 | B29: 41 | C29: 81 | D29: ="Propina - "&Mensalidades!B10&" Set/26" -> Propina - Gael Hanji Ventura Quimbundo Set/26 | E29: =IF(Mensalidades!E10>0,Mensalidades!E10,"") | F29: =Mensalidades!A10 -> P3-05 | G29: =Mensalidades!B10 -> Gael Hanji Ventura Quimbundo | H29: Propina
A30: 46270 | B30: 41 | C30: 81 | D30: ="Propina - "&Mensalidades!B11&" Set/26" -> Propina - Ivanna Chayane Bernardo Clementino Set/26 | E30: =IF(Mensalidades!E11>0,Mensalidades!E11,"") | F30: =Mensalidades!A11 -> P3-06 | G30: =Mensalidades!B11 -> Ivanna Chayane Bernardo Clementino | H30: Propina
A31: 46270 | B31: 41 | C31: 81 | D31: ="Propina - "&Mensalidades!B12&" Set/26" -> Propina - Wendy Aryanne Chimuco Sabino Set/26 | E31: =IF(Mensalidades!E12>0,Mensalidades!E12,"") | F31: =Mensalidades!A12 -> P3-07 | G31: =Mensalidades!B12 -> Wendy Aryanne Chimuco Sabino | H31: Propina
A32: 46270 | B32: 41 | C32: 81 | D32: ="Propina - "&Mensalidades!B19&" Set/26" -> Propina - Set/26 | E32: =IF(Mensalidades!E19>0,Mensalidades!E19,"") | F32: =Mensalidades!A19 | G32: =Mensalidades!B19 | H32: Propina
A33: 46270 | B33: 41 | C33: 81 | D33: ="Propina - "&Mensalidades!B20&" Set/26" -> Propina - Set/26 | E33: =IF(Mensalidades!E20>0,Mensalidades!E20,"") | F33: =Mensalidades!A20 | G33: =Mensalidades!B20 | H33: Propina
A34: 46270 | B34: 41 | C34: 81 | D34: ="Propina - "&Mensalidades!B25&" Set/26" -> Propina - Set/26 | E34: =IF(Mensalidades!E25>0,Mensalidades!E25,"") | F34: =Mensalidades!A25 | G34: =Mensalidades!B25 | H34: Propina
D40: TOTAL MENSALIDADES | E40: =SUM(E25:E37) -> 0
D42: TOTAL GERAL | E42: =E21+E40 -> 1712000
A44: EMPRÉSTIMO / ADIANTAMENTO DO SÓCIO (Arranque)
A45: Data | B45: Debito | C45: Credito | D45: Descricao | E45: Valor | F45: Ref. | G45: Categoria | H45: Fonte
A46: 46187 | B46: 41 | C46: Empréstimo Sócio | D46: Entrada de capital do sócio (total despesas de arranque) | E46: =E67 -> 4988379.9 | F46: FAT-001 | G46: Empréstimo Sócio | H46: Adiantamentos_Emprestimos
D47: TOTAL EMPRÉSTIMO SÓCIO | E47: =E67 -> 4988379.9
A49: DESPESAS DE ARRANQUE (financiadas pelo empréstimo do sócio)
A50: Data | B50: Debito | C50: Credito | D50: Descricao | E50: Valor | F50: Ref. | G50: Categoria | H50: Fonte
A51: 46218 | B51: Pintura Exterior | C51: 41 | D51: Despesas de arranque – Pintura Exterior | E51: 1093730 | F51: Arranque | G51: Pintura Exterior | H51: Adiantamentos_Emprestimos
A52: 46223 | B52: Serralharia | C52: 41 | D52: Despesas de arranque – Serralharia | E52: 1208000 | F52: Arranque | G52: Serralharia | H52: Adiantamentos_Emprestimos
...

Sheet Fluxo de Caixa
A1: FLUXO DE CAIXA – Ano Letivo 2026/2027
A3: Mês | B3: Entradas Inscrições | C3: Entradas Propinas | D3: Entradas Extras | E3: Entradas Outras | F3: Total Entradas | G3: Saídas | H3: Saldo
